Workbook

Sheet Nov2025
A1: Room | B1: Type | C1: 1 | D1: 2 | E1: 3 | F1: 4 | G1: 5 | H1: 6 | I1: 7 | J1: 8 | K1: 9 | L1: 10 | M1: 11 | N1: 12 | O1: 13 | P1: 14 | Q1: 15 | R1: 16 | S1: 17 | T1: 18 | U1: 19 | V1: 20 | W1: 21 | X1: 22 | Y1: 23 | Z1: 24 | AA1: 25 | AB1: 26 | AC1: 27 | AD1: 28 | AE1: 29 | AF1: 30
C2: Sat | D2: Sun | E2: Mon | F2: Tue | G2: Wed | H2: Thu | I2: Fri | J2: Sat | K2: Sun | L2: Mon | M2: Tue | N2: Wed | O2: Thu | P2: Fri | Q2: Sat | R2: Sun | S2: Mon | T2: Tue | U2: Wed | V2: Thu | W2: Fri | X2: Sat | Y2: Sun | Z2: Mon | AA2: Tue | AB2: Wed | AC2: Thu | AD2: Fri | AE2: Sat | AF2: Sun
A3: 1 | B3: Single | C3: Ruben Strik 2 rooms | D3: 1 | E3: Rebecca Blanche | I3: Korel Mikail Yolcu | N3: Lijana Vespenderiene จำนวน 2 ห้อง DD/SD | R3: Viktorija Risteska | V3: Marina Keller | Z3: Davy Gauci | AC3: Ophelia Ooi | AF3: Nick McCafferty
A4: 2 | B4: Single | D4: Sven Erich Szymaniak | F4: Rodrigo Francisco Pereira Leite | J4: Rune Klima Olsen | M4: Welmoed Bouma | P4: André Reichelt | S4: Gustavo Guimaraes Morato Abreu | U4: Alba Canto 3 room | X4: 1 | Y4: David Matten | AB4: nicola feller | AF4: Chang-An Wang
A5: 3 | B5: Single Queen | C5: Josh Elliott | F5: Mikayla Scells | J5: 1 | K5: Felix Luenzer 19:00 - 20:00 | N5: Lijana Vespenderiene จำนวน 2 ห้อง DD/SD | R5: Sarah Simon | W5: Karolina Bełdzińska-Gądek | Z5: 1 | AA5: Monica Sacchiero | AD5: Felix Luenzer
A6: 4 | B6: Twin Bed | C6: Nikol Ziukina | E6: 1 | F6: Bruce Locke | I6: Kirsten Lee | L6: Gwenllian Jones / Make to King Size Bed | Q6: YI YUN CHEN 5:00 PM ถึง 6:00 PM | S6: ฟาง | Z6: 1 | AA6: Elise Kerckhofs | AF6: Olga Wilk
A7: 5 | B7: Twin Bed | C7: Shaun Blum upgrade TWIN->SUITE | D7: 1 | E7: 1 | F7: raphael lesca | H7: Valotaire franckie / Requested 10:00 | K7: Extend 1,000 (Paid) | L7: Aksa Papilaja | Q7: Ursula Kämpfer | T7: Kamolchai | U7: Alba Canto 3 room | X7: 1 | Y7: Tiago Emanuel Pereira Nunes 12:00 PM ถึง 1:00 PM | AC7: 雅晴 張
A8: 6 | B8: Single | C8: Lotte Seinen | F8: Pedro Biagi de Almeida | J8: Vyet Voppen | M8: Callie Currier | P8: Brendan Dunn | T8: Jasmin Andersson / Need Window | AA8: Mara van Tiggelen | AF8: JIN, YURIM
A9: 7 | B9: Single | C9: Tia Pietrek | I9: Ting Yi Shen | J9: Jennifer Mason | N9: Htet Myat Aung | R9: 1 | S9: Khun Alice 1000x3 | W9: Jean-Baptiste Druet | AA9: Maren Pietzonka | AE9: Lee Yee Dian (4 room same group)
A10: 8 | B10: Single | C10: Campbell Azrielle | J10: 1 | K10: Grzegorz Hołod | O10: 1 | P10: Laura Udri | T10: Charlotte Wicht | X10: Moira Smets 4:00 PM- 5:00 PM | AB10: James Clothier | AE10: Lee Fun Thoo เตียงเดียว (4 room same group)
A11: 9 | B11: Single Queen | C11: Daniel Bernardes | E11: Daniel อยู่เพิ่ม 900 | F11: Raphaël Egeley | H11: Yanizel Llorent | M11: 1 | N11: Fer Rodriguez | Q11: Hanna Kalchschmid | U11: Irene Hervás | X11: Galina Bashurova | AB11: merve taskan / 8:00 AM ถึง 9:00 AM | AE11: Kanat Tabaldiev
A12: 10 | B12: Twin Bed | C12: Marlotte Jansen | D12: Pospawin Chinpeerasatian | F12: Angel Espejo | J12: 1 | K12: Ricardo Coelho | N12: Niklas Savijoki | T12: 1 | U12: Alba Canto 3 room | X12: Su Yadanar Kyaw | Z12: Marie Plankensteiner | AC12: 1 | AD12: 1 | AE12: Yong Chai Fung (4 room same group)
A13: 11 | B13: Twin Bed | C13: Denisa Mensatorisová | E13: Albertas Gustis | J13: Sino Piroty-Dehbokry | L13: Christine Nelson | Q13: Wekoweu Tsuha | U13: Jose Castro | W13: Cathy Kao | Z13: Beatriz Canelas de Oliveira | AC13: Wojciech Zdeb | AE13: Lee Fun Thoo เตียงเดียว (4 room same group)
A14: 12 | B14: Single | C14: Paola Andrea Vega Vega Otero | J14: 1 | K14: Klages Debi | X14: Carlos Alberto Franco Perez | AB14: Angela Ngan | AE14: 1 | AF14: Aleksandra Kreczmańska
A15: Suite | B15: Honeymoon | C15: Stephanie Scuorzo | D15: 1 | J15: Christoph Gallowitsch / 15:00-16:00 | O15: Megan Park | R15: DAHAE KIM | T15: Hendrik Esselink | W15: Felix Luenzer | Z15: Wojciech Janczuk | AE15: Tamara Tubic
C16: =(30*13-SUM(C17:AF20))/(30*13) -> #REF!
B17: Superiroe | C17: =C28+C34 -> 0 | D17: =D28+D34 -> 0 | E17: =E28+E34 -> 0 | F17: =F28+F34 -> 0 | G17: =G28+G34 -> 0 | H17: =H28+H34 -> 0 | I17: =I28+I34 -> 0 | J17: =J28+J34 -> 1 | ... AF17: =AF28+AF34 -> 0
B18: Deluxe Double | C18: =C26+C27+C31+C32+C33+C37 -> 0 | D18: =D26+D27+D31+D32+D33+D37 -> 1 | E18: =E26+E27+E31+E32+E33+E37 -> 0 | F18: =F26+F27+F31+F32+F33+F37 -> 0 | G18: =G26+G27+G31+G32+G33+G37 -> 0 | H18: =H26+H27+H31+H32+H33+H37 -> 0 | I18: =I26+I27+I31+I32+I33+I37 -> 0 | J18: =J26+J27+J31+J32+J33+J37 -> 2 | ... AF18: =AF26+AF27+AF31+AF32+AF33+AF37 -> 0
B19: DeluxeTwin | C19: =C29+C30+C35+C36 -> 0 | D19: =D29+D30+D35+D36 -> 1 | E19: =E29+E30+E35+E36 -> 2 | F19: =F29+F30+F35+F36 -> 0 | G19: =G29+G30+G35+G36 -> 0 | H19: =H29+H30+H35+H36 -> 0 | I19: =I29+I30+I35+I36 -> 0 | J19: =J29+J30+J35+J36 -> 1 | ... AF19: =AF29+AF30+AF35+AF36 -> 0
B20: Honeymoon Suite | C20: =C38 -> 0 | D20: =D38 -> 1 | E20: =E38 -> 0 | F20: =F38 -> 0 | G20: =G38 -> 0 | H20: =H38 -> 0 | I20: =I38 -> 0 | J20: =J38 -> 0 | ... AF20: =AF38 -> 0
C21: =SUM(C17:C20) -> 0 | D21: =SUM(D17:D20) -> 3 | E21: =SUM(E17:E20) -> 2 | F21: =SUM(F17:F20) -> 0 | G21: =SUM(G17:G20) -> 0 | H21: =SUM(H17:H20) -> 0 | I21: =SUM(I17:I20) -> 0 | J21: =SUM(J17:J20) -> 4 | ... AF21: =SUM(AF17:AF20) -> 0
B26: 1 | C26: =IF(C3=1,1,0) -> 0 | D26: =IF(D3=1,1,0) -> 1 | E26: =IF(E3=1,1,0) -> 0 | F26: =IF(F3=1,1,0) -> 0 | G26: =IF(G3=1,1,0) -> 0 | H26: =IF(H3=1,1,0) -> 0 | I26: =IF(I3=1,1,0) -> 0 | J26: =IF(J3=1,1,0) -> 0 | ... Y26: =IF(Y3=1,1,0) -> 0 | Z26: =IF(V3=1,1,0) -> 0 | AA26: =IF(AA3=1,1,0) -> 0 | AB26: =IF(AB3=1,1,0) -> 0 | AC26: =IF(AC3=1,1,0) -> 0 | AD26: =IF(AD3=1,1,0) -> 0 | AE26: =IF(AE3=1,1,0) -> 0 | AF26: =IF(AF3=1,1,0) -> 0
B27: 2 | C27: =IF(C4=1,1,0) -> 0 | D27: =IF(D4=1,1,0) -> 0 | E27: =IF(E4=1,1,0) -> 0 | F27: =IF(F4=1,1,0) -> 0 | G27: =IF(G4=1,1,0) -> 0 | H27: =IF(H4=1,1,0) -> 0 | I27: =IF(I4=1,1,0) -> 0 | J27: =IF(J4=1,1,0) -> 0 | ... AF27: =IF(AF4=1,1,0) -> 0
B28: 3 | C28: =IF(C5=1,1,0) -> 0 | D28: =IF(D5=1,1,0) -> 0 | E28: =IF(E5=1,1,0) -> 0 | F28: =IF(F5=1,1,0) -> 0 | G28: =IF(G5=1,1,0) -> 0 | H28: =IF(H5=1,1,0) -> 0 | I28: =IF(I5=1,1,0) -> 0 | J28: =IF(J5=1,1,0) -> 1 | ... AF28: =IF(AF5=1,1,0) -> 0
B29: 4 | C29: =IF(C6=1,1,0) -> 0 | D29: =IF(D6=1,1,0) -> 0 | E29: =IF(E6=1,1,0) -> 1 | F29: =IF(F6=1,1,0) -> 0 | G29: =IF(G6=1,1,0) -> 0 | H29: =IF(H6=1,1,0) -> 0 | I29: =IF(I6=1,1,0) -> 0 | J29: =IF(J6=1,1,0) -> 0 | ... AF29: =IF(AF6=1,1,0) -> 0
B30: 5 | C30: =IF(C7=1,1,0) -> 0 | D30: =IF(D7=1,1,0) -> 1 | E30: =IF(E7=1,1,0) -> 1 | F30: =IF(F7=1,1,0) -> 0 | G30: =IF(G7=1,1,0) -> 0 | H30: =IF(H7=1,1,0) -> 0 | I30: =IF(I7=1,1,0) -> 0 | J30: =IF(J7=1,1,0) -> 0 | K30: =IF(K7=1,1,0) -> 0 | L30: =IF(#REF!=1,1,0) -> #REF! | M30: =IF(M7=1,1,0) -> 0 | N30: =IF(N7=1,1,0) -> 0 | O30: =IF(L7=1,1,0) -> 0 | P30: =IF(P7=1,1,0) -> 0 | Q30: =IF(Q7=1,1,0) -> 0 | R30: =IF(R7=1,1,0) -> 0 | S30: =IF(S7=1,1,0) -> 0 | T30: =IF(T7=1,1,0) -> 0 | U30: =IF(U7=1,1,0) -> 0 | V30: =IF(V7=1,1,0) -> 0 | W30: =IF(W7=1,1,0) -> 0 | ... AF30: =IF(AF7=1,1,0) -> 0
B31: 6 | C31: =IF(C8=1,1,0) -> 0 | D31: =IF(D8=1,1,0) -> 0 | E31: =IF(E8=1,1,0) -> 0 | F31: =IF(F8=1,1,0) -> 0 | G31: =IF(G8=1,1,0) -> 0 | H31: =IF(H8=1,1,0) -> 0 | I31: =IF(I8=1,1,0) -> 0 | J31: =IF(J8=1,1,0) -> 0 | ... AF31: =IF(AF8=1,1,0) -> 0
B32: 7 | C32: =IF(C9=1,1,0) -> 0 | D32: =IF(D9=1,1,0) -> 0 | E32: =IF(E9=1,1,0) -> 0 | F32: =IF(F9=1,1,0) -> 0 | G32: =IF(G9=1,1,0) -> 0 | H32: =IF(H9=1,1,0) -> 0 | I32: =IF(I9=1,1,0) -> 0 | J32: =IF(J9=1,1,0) -> 0 | ... AF32: =IF(AF9=1,1,0) -> 0
B33: 8 | C33: =IF(C10=1,1,0) -> 0 | D33: =IF(D10=1,1,0) -> 0 | E33: =IF(E10=1,1,0) -> 0 | F33: =IF(F10=1,1,0) -> 0 | G33: =IF(G10=1,1,0) -> 0 | H33: =IF(H10=1,1,0) -> 0 | I33: =IF(I10=1,1,0) -> 0 | J33: =IF(J10=1,1,0) -> 1 | ... AF33: =IF(AF10=1,1,0) -> 0
B34: 9 | C34: =IF(C11=1,1,0) -> 0 | D34: =IF(D11=1,1,0) -> 0 | E34: =IF(E11=1,1,0) -> 0 | F34: =IF(F11=1,1,0) -> 0 | G34: =IF(G11=1,1,0) -> 0 | H34: =IF(H11=1,1,0) -> 0 | I34: =IF(I11=1,1,0) -> 0 | J34: =IF(J11=1,1,0) -> 0 | ... AF34: =IF(AF11=1,1,0) -> 0
B35: 10 | C35: =IF(C12=1,1,0) -> 0 | D35: =IF(D12=1,1,0) -> 0 | E35: =IF(E12=1,1,0) -> 0 | F35: =IF(F12=1,1,0) -> 0 | G35: =IF(G12=1,1,0) -> 0 | H35: =IF(H12=1,1,0) -> 0 | I35: =IF(I12=1,1,0) -> 0 | J35: =IF(J12=1,1,0) -> 1 | ... AF35: =IF(AF12=1,1,0) -> 0
B36: 11 | C36: =IF(C13=1,1,0) -> 0 | D36: =IF(D13=1,1,0) -> 0 | E36: =IF(E13=1,1,0) -> 0 | F36: =IF(F13=1,1,0) -> 0 | G36: =IF(G13=1,1,0) -> 0 | H36: =IF(H13=1,1,0) -> 0 | I36: =IF(I13=1,1,0) -> 0 | J36: =IF(J13=1,1,0) -> 0 | ... AF36: =IF(AF13=1,1,0) -> 0
B37: 12 | C37: =IF(C14=1,1,0) -> 0 | D37: =IF(D14=1,1,0) -> 0 | E37: =IF(E14=1,1,0) -> 0 | F37: =IF(F14=1,1,0) -> 0 | G37: =IF(G14=1,1,0) -> 0 | H37: =IF(H14=1,1,0) -> 0 | I37: =IF(I14=1,1,0) -> 0 | J37: =IF(J14=1,1,0) -> 1 | ... AF37: =IF(AF14=1,1,0) -> 0
B38: Suite | C38: =IF(C15=1,1,0) -> 0 | D38: =IF(D15=1,1,0) -> 1 | E38: =IF(E15=1,1,0) -> 0 | F38: =IF(F15=1,1,0) -> 0 | G38: =IF(G15=1,1,0) -> 0 | H38: =IF(H15=1,1,0) -> 0 | I38: =IF(I15=1,1,0) -> 0 | J38: =IF(J15=1,1,0) -> 0 | ... AF38: =IF(AF15=1,1,0) -> 0

Sheet Dec2025
A1: Room | B1: Type | C1: 1 | D1: 2 | E1: 3 | F1: 4 | G1: 5 | H1: 6 | I1: 7 | J1: 8 | K1: 9 | L1: 10 | M1: 11 | N1: 12 | O1: 13 | P1: 14 | Q1: 15 | R1: 16 | S1: 17 | T1: 18 | U1: 19 | V1: 20 | W1: 21 | X1: 22 | Y1: 23 | Z1: 24 | AA1: 25 | AB1: 26 | AC1: 27 | AD1: 28 | AE1: 29 | AF1: 30 | AG1: 31
C2: Mon | D2: Tue | E2: Wed | F2: Thu | G2: Fri | H2: Sat | I2: Sun | J2: Mon | K2: Tue | L2: Wed | M2: Thu | N2: Fri | O2: Sat | P2: Sun | Q2: Mon | R2: Tue | S2: Wed | T2: Thu | U2: Fri | V2: Sat | W2: Sun | X2: Mon | Y2: Tue | Z2: Wed | AA2: Thu | AB2: Fri | AC2: Sat | AD2: Sun | AE2: Mon | AF2: Tue | AG2: Wed
A3: 1 | B3: Single | C3: Nick McCafferty | E3: Silja Glismann | J3: Cornelis Jan Van Ekris | N3: April Russum | S3: 1 | T3: Michael Dawson | AA3: Xiaoning CAI | AE3: MARCO MASSI 10:00 - 11:00
A4: 2 | B4: Single | C4: Chang-An Wang | E4: Dominic O’Malley | H4: Olivia Baumann | M4: Enrique Gonzalez Nieto | Q4: sabrine laribi 18:00 - 19:00 | T4: Di Giovacchino Luana / Day Trip Chiang Rai | Y4: Diego Varoli Piazza
A5: 3 | B5: Single Queen | C5: Alison Yao Sdx1, DTx1 | E5: Elizabeth Lee / knee injury. | I5: Vanessa Wander | L5: Eszter Kovacs | O5: Elizabeth Le | S5: Ronan Butler | V5: Alexander Brune | Y5: 1 | Z5: Vincent Sitwell จำนวน 2 ห้อง | AG5: YihuiChi
A6: 4 | B6: Twin Bed | C6: Olga Wilk | E6: Marina Pitterich | H6: Bille Tierney (3:00-4:00PM) | K6: 1 | L6: Mario Díaz García | O6: Ivana Osičková | R6: 1 | S6: 1 | T6: Kohei Akiyama | X6: 1 | Y6: Haichen` Huang | AB6: Laila Benani | AE6: Buddy Wijesekara | AG6: Tal Nahoom
A7: 5 | B7: Twin Bed | C7: Alison Yao Sdx1, DTx1 | E7: Julian Schmidberger มารถไฟถึงเช้า | H7: Arnaud Moulas | L7: Karoly Karakas | O7: Freidhof Serena | R7: Hasan Turalic | U7: Hay Mar Hlaing | Y7: Joanna Wieczorek | AD7: 1 | AE7: Louise Johansson
A8: 6 | B8: Single | C8: JIN, YURIM | E8: jani Silva | K8: Chidchanok Promraksa | O8: Antonino Borgese / noise complaint | R8: 1 | S8: Batikan Koleoglu | W8: Emma Venuat | AA8: Ourania Vourvachaki | AD8: 1 | AE8: kanthamanee waenvised
A9: 7 | B9: Single | C9: Lee Yee Dian (4 room same group) | F9: soufiane lemrani | I9: Carmel Ball | L9: Anna Schroeder | O9: shannon riches | T9: Ilena Maslac ถึงเที่ยงคืน 23:00-00:00 | Z9: Daniele Carati | AD9: 1 | AE9: Florence MARCÉ ชั้นสูง 3:00 PM ถึง 4:00 PM
A10: 8 | B10: Single | C10: Lee Fun Thoo เตียงเดียว (4 room same group) | F10: Victoria Lago / Check in 01:00 on 5/12/2025 | L10: Kati Liibak | P10: Bo Bi 21:00 - 22:00 | T10: Magdalena Styczen 22:00-23:00 | Y10: Iana Sizhazheva | AA10: rong deng | AD10: Lauren Minter | AG10: Paul Trujillo
A11: 9 | B11: Single Queen | C11: Kanat Tabaldiev | E11: Houjie Qiu early check in 1,000 | F11: Houjie Qiu | I11: Elodie Martin-laval | K11: Laura Davis | N11: Francois Dubois | S11: virginie proaskat | W11: Sofia Luis | Z11: Vincent Sitwell จำนวน 2 ห้อง | AF11: Sutthiphong Pannil
A12: 10 | B12: Twin Bed | C12: Yong Chai Fung (4 room same group) | F12: Sofia Hevia | K12: JESUS RUBEN ROCHIN PARRA | R12: Jonathan Kantor | U12: CHENG WEN LEE 22:00 - 23:00 | AA12: Xin Qiao | AD12: 1 | AE12: ERIKA MIYAJI 10:00 PM ถึง 11:00 PM
A13: 11 | B13: Twin Bed | C13: Lee Fun Thoo เตียงเดียว (4 room same group) | F13: David Carvajal del Pozo | J13: Jack Howell 11-12 pm | P13: 1 | Q13: 1 | R13: Fangzhou Liu | U13: Adrian Cabrejo Pinto | Z13: Adam O’Donnell | AD13: BY Bahroelim | AF13: Strong Tracy
A14: 12 | B14: Single | C14: Aleksandra Kreczmańska | E14: Quang Dieu Hoang Le | I14: Dijana Duloric | L14: Pamela Liou | Q14: Cristian GRIGORIU | V14: Isabel Louza | Y14: Bibiana Eggenhofer | AC14: Buddy Wijesekara | AE14: Camilla Ditz Vagner
A15: Suite | B15: Honeymoon | C15: Tamara Tubic | D15: Gizem Reimann ย้ายไป Roseate 3 คืน 2,3,4 | F15: พี่ปอ 2,400 | H15: Steven Molter | L15: Jeanette Herb | P15: 1 | Q15: Patrick Lodes | V15: Michael Gertner | Y15: Christophe Capeau | AB15: JIE GAO | AE15: MONTANA SINPRASERT
C16: =(31*13-SUM(C18:AG21))/(31*13) -> 0.96526055
B18: Superiroe | C18: =C29+C35 -> 0 | D18: =D29+D35 -> 0 | E18: =E29+E35 -> 0 | F18: =F29+F35 -> 0 | G18: =G29+G35 -> 0 | H18: =H29+H35 -> 0 | I18: =I29+I35 -> 0 | J18: =J29+J35 -> 0 | ... AG18: =AG29+AG35 -> 0
B19: Deluxe Double | C19: =C27+C28+C32+C33+C34+C38 -> 0 | D19: =D27+D28+D32+D33+D34+D38 -> 0 | E19: =E27+E28+E32+E33+E34+E38 -> 0 | F19: =F27+F28+F32+F33+F34+F38 -> 0 | G19: =G27+G28+G32+G33+G34+G38 -> 0 | H19: =H27+H28+H32+H33+H34+H38 -> 0 | I19: =I27+I28+I32+I33+I34+I38 -> 0 | J19: =J27+J28+J32+J33+J34+J38 -> 0 | ... AG19: =AG27+AG28+AG32+AG33+AG34+AG38 -> 0
B20: DeluxeTwin | C20: =C30+C31+C36+C37 -> 0 | D20: =D30+D31+D36+D37 -> 0 | E20: =E30+E31+E36+E37 -> 0 | F20: =F30+F31+F36+F37 -> 0 | G20: =G30+G31+G36+G37 -> 0 | H20: =H30+H31+H36+H37 -> 0 | I20: =I30+I31+I36+I37 -> 0 | J20: =J30+J31+J36+J37 -> 0 | ... AG20: =AG30+AG31+AG36+AG37 -> 0
B21: Honeymoon Suite | C21: =C39 -> 0 | D21: =D39 -> 0 | E21: =E39 -> 0 | F21: =F39 -> 0 | G21: =G39 -> 0 | H21: =H39 -> 0 | I21: =I39 -> 0 | J21: =J39 -> 0 | ... AG21: =AG39 -> 0
C22: =SUM(C18:C21) -> 0 | D22: =SUM(D18:D21) -> 0 | E22: =SUM(E18:E21) -> 0 | F22: =SUM(F18:F21) -> 0 | G22: =SUM(G18:G21) -> 0 | H22: =SUM(H18:H21) -> 0 | I22: =SUM(I18:I21) -> 0 | J22: =SUM(J18:J21) -> 0 | ... AG22: =SUM(AG18:AG21) -> 0
B27: 1 | C27: =IF(C3=1,1,0) -> 0 | D27: =IF(D3=1,1,0) -> 0 | E27: =IF(E3=1,1,0) -> 0 | F27: =IF(F3=1,1,0) -> 0 | G27: =IF(G3=1,1,0) -> 0 | H27: =IF(H3=1,1,0) -> 0 | I27: =IF(I3=1,1,0) -> 0 | J27: =IF(J3=1,1,0) -> 0 | ... AG27: =IF(AG3=1,1,0) -> 0
B28: 2 | C28: =IF(C4=1,1,0) -> 0 | D28: =IF(D4=1,1,0) -> 0 | E28: =IF(E4=1,1,0) -> 0 | F28: =IF(F4=1,1,0) -> 0 | G28: =IF(G4=1,1,0) -> 0 | H28: =IF(H4=1,1,0) -> 0 | I28: =IF(I4=1,1,0) -> 0 | J28: =IF(J4=1,1,0) -> 0 | ... AG28: =IF(AG4=1,1,0) -> 0
B29: 3 | C29: =IF(C5=1,1,0) -> 0 | D29: =IF(D5=1,1,0) -> 0 | E29: =IF(E5=1,1,0) -> 0 | F29: =IF(F5=1,1,0) -> 0 | G29: =IF(G5=1,1,0) -> 0 | H29: =IF(H5=1,1,0) -> 0 | I29: =IF(I5=1,1,0) -> 0 | J29: =IF(J5=1,1,0) -> 0 | ... AG29: =IF(AG5=1,1,0) -> 0
B30: 4 | C30: =IF(C6=1,1,0) -> 0 | D30: =IF(D6=1,1,0) -> 0 | E30: =IF(E6=1,1,0) -> 0 | F30: =IF(F6=1,1,0) -> 0 | G30: =IF(G6=1,1,0) -> 0 | H30: =IF(H6=1,1,0) -> 0 | I30: =IF(I6=1,1,0) -> 0 | J30: =IF(J6=1,1,0) -> 0 | ... AG30: =IF(AG6=1,1,0) -> 0
B31: 5 | C31: =IF(C7=1,1,0) -> 0 | D31: =IF(D7=1,1,0) -> 0 | E31: =IF(E7=1,1,0) -> 0 | F31: =IF(F7=1,1,0) -> 0 | G31: =IF(G7=1,1,0) -> 0 | H31: =IF(H7=1,1,0) -> 0 | I31: =IF(I7=1,1,0) -> 0 | J31: =IF(J7=1,1,0) -> 0 | ... AG31: =IF(AG7=1,1,0) -> 0
B32: 6 | C32: =IF(C8=1,1,0) -> 0 | D32: =IF(D8=1,1,0) -> 0 | E32: =IF(E8=1,1,0) -> 0 | F32: =IF(F8=1,1,0) -> 0 | G32: =IF(G8=1,1,0) -> 0 | H32: =IF(H8=1,1,0) -> 0 | I32: =IF(I8=1,1,0) -> 0 | J32: =IF(J8=1,1,0) -> 0 | ... AG32: =IF(AG8=1,1,0) -> 0
B33: 7 | C33: =IF(C9=1,1,0) -> 0 | D33: =IF(D9=1,1,0) -> 0 | E33: =IF(E9=1,1,0) -> 0 | F33: =IF(F9=1,1,0) -> 0 | G33: =IF(G9=1,1,0) -> 0 | H33: =IF(H9=1,1,0) -> 0 | I33: =IF(I9=1,1,0) -> 0 | J33: =IF(J9=1,1,0) -> 0 | ... AG33: =IF(AG9=1,1,0) -> 0
B34: 8 | C34: =IF(C10=1,1,0) -> 0 | D34: =IF(D10=1,1,0) -> 0 | E34: =IF(E10=1,1,0) -> 0 | F34: =IF(F10=1,1,0) -> 0 | G34: =IF(G10=1,1,0) -> 0 | H34: =IF(H10=1,1,0) -> 0 | I34: =IF(I10=1,1,0) -> 0 | J34: =IF(J10=1,1,0) -> 0 | ... AG34: =IF(AG10=1,1,0) -> 0
B35: 9 | C35: =IF(C11=1,1,0) -> 0 | D35: =IF(D11=1,1,0) -> 0 | E35: =IF(E11=1,1,0) -> 0 | F35: =IF(F11=1,1,0) -> 0 | G35: =IF(G11=1,1,0) -> 0 | H35: =IF(H11=1,1,0) -> 0 | I35: =IF(I11=1,1,0) -> 0 | J35: =IF(J11=1,1,0) -> 0 | ... AG35: =IF(AG11=1,1,0) -> 0
B36: 10 | C36: =IF(C12=1,1,0) -> 0 | D36: =IF(D12=1,1,0) -> 0 | E36: =IF(E12=1,1,0) -> 0 | F36: =IF(F12=1,1,0) -> 0 | G36: =IF(G12=1,1,0) -> 0 | H36: =IF(H12=1,1,0) -> 0 | I36: =IF(I12=1,1,0) -> 0 | J36: =IF(J12=1,1,0) -> 0 | ... AG36: =IF(AG12=1,1,0) -> 0
B37: 11 | C37: =IF(C13=1,1,0) -> 0 | D37: =IF(D13=1,1,0) -> 0 | E37: =IF(E13=1,1,0) -> 0 | F37: =IF(F13=1,1,0) -> 0 | G37: =IF(G13=1,1,0) -> 0 | H37: =IF(H13=1,1,0) -> 0 | I37: =IF(I13=1,1,0) -> 0 | J37: =IF(J13=1,1,0) -> 0 | ... AG37: =IF(AG13=1,1,0) -> 0
B38: 12 | C38: =IF(C14=1,1,0) -> 0 | D38: =IF(D14=1,1,0) -> 0 | E38: =IF(E14=1,1,0) -> 0 | F38: =IF(F14=1,1,0) -> 0 | G38: =IF(G14=1,1,0) -> 0 | H38: =IF(H14=1,1,0) -> 0 | I38: =IF(I14=1,1,0) -> 0 | J38: =IF(J14=1,1,0) -> 0 | ... AG38: =IF(AG14=1,1,0) -> 0
B39: Suite | C39: =IF(C15=1,1,0) -> 0 | D39: =IF(D15=1,1,0) -> 0 | E39: =IF(E15=1,1,0) -> 0 | F39: =IF(F15=1,1,0) -> 0 | G39: =IF(G15=1,1,0) -> 0 | H39: =IF(H15=1,1,0) -> 0 | I39: =IF(I15=1,1,0) -> 0 | J39: =IF(J15=1,1,0) -> 0 | ... AG39: =IF(AG15=1,1,0) -> 0

Sheet Jan2026
A1: Room | B1: Type | C1: 1 | D1: 2 | E1: 3 | F1: 4 | G1: 5 | H1: 6 | I1: 7 | J1: 8 | K1: 9 | L1: 10 | M1: 11 | N1: 12 | O1: 13 | P1: 14 | Q1: 15 | R1: 16 | S1: 17 | T1: 18 | U1: 19 | V1: 20 | W1: 21 | X1: 22 | Y1: 23 | Z1: 24 | AA1: 25 | AB1: 26 | AC1: 27 | AD1: 28 | AE1: 29 | AF1: 30 | AG1: 31 | AH1: 1 | AI1: 2 | AJ1: 3 | AK1: 4 | AL1: 5 | AM1: 6 | AN1: 7
C2: Thu | D2: Fri | E2: Sat | F2: Sun | G2: Mon | H2: Tue | I2: Wed | J2: Thu | K2: Fri | L2: Sat | M2: Sun | N2: Mon | O2: Tue | P2: Wed | Q2: Thu | R2: Fri | S2: Sat | T2: Sun | U2: Mon | V2: Tue | W2: Wed | X2: Thu | Y2: Fri | Z2: Sat | AA2: Sun | AB2: Mon | AC2: Tue | AD2: Wed | AE2: Thu | AF2: Fri | AG2: Sat | AH2: Sun | AI2: Mon | AJ2: Tue | AK2: Wed | AL2: Thu | AM2: Fri | AN2: Sat
A3: 1 | B3: Single | C3: Viola Rotelli (2 room book) | F3: Joel Van De Sluis | J3: Mikayla Rawluk | M3: Fanny Uhlin | P3: Jan Meyer ( 2 room book ) | U3: Abbey Killoran ( 2 room book ) | Y3: Marcel Rothe | AB3: 1 | AC3: Zolin Leoni | AF3: Anna Anguera Reverté | AH3: Anna Anguera Reverté | AI3: Romane Million | AL3: Robert Lislois
A4: 2 | B4: Single | F4: Marie Luisa Kuntz | H4: Andrzej Sudenis | K4: 1 | L4: Yu-Syuan Chang | O4: Althea Mallee | R4: Charlie Gladding | Y4: Ilona Klamann | AA4: Irene cannavò | AD4: Lee Sweeney | AG4: richard kelly | AH4: richard kelly
A5: 3 | B5: Single Queen | C5: Yihul Chi | F5: Lara Hunt | J5: Maria Koraki | O5: Joaquim Guerreiro 17:00 - 18:00 | R5: Jill Röhr | U5: Marius Schult | Z5: 1 | AA5: Camila Fernandes Vidal | AF5: Michelle Huang | AH5: Michelle Huang | AI5: Adelina Dopico López | AL5: Mattea Grech
A6: 4 | B6: Twin Bed | C6: Tal Nahoom | F6: David Simonian | H6: David Furley | K6: WENRU GAO | M6: Leah Humphrey | Q6: David López | T6: Aleksandra Bochkareva | W6: Swetha Srinath / ลูกค้าขอชิดเตียง / Make to Kid bed | Z6: jean-michel gabilly | AF6: Laura Munoz | AH6: Laura Munoz | AI6: JANE SELIA DOS REIS COIMBRA
A7: 5 | B7: Twin Bed | C7: Louise Johansson | E7: Daisy Arendell | H7: Iwona Kulińska-Ambroziak | K7: Oliver Andersson / Arrive 10 Jan on 6:00am | Q7: Renee Ju ( 2 room booking ) | U7: Helen Truscott | Z7: 1 | AA7: Roland Galensowske | AH7: 1 | AI7: 1 | AJ7: Deborah Young
A8: 6 | B8: Single | C8: kanthamanee waenvised | E8: Lisanne Meijer | J8: Yaquelin Prado | N8: Lisanne Meijer | V8: Gunilla Nyberg | Z8: Owain Ashley Jones | AC8: Dominic Panunzio | AF8: youcyuan lin | AH8: youcyuan lin | AI8: 1 | AJ8: Ambrosio James | AN8: 1
A9: 7 | B9: Single | C9: Florence MARCÉ | F9: Joris Toselli | K9: Nutchanka Manoch | N9: Juri Hartmann | S9: Ebba Wahlberg | W9: Walter Fischer | AA9: Lim Jia Qi | AG9: Florian Poppelmann | AH9: Florian Pöppelmann | AK9: Annika Ramesh
A10: 8 | B10: Single | C10: Paul Trujillo | E10: Emilie Stefan ( 2 room book ) | I10: Gary Joyce จำนวน 3 ห้อง | L10: Hanoe Cornet | P10: Jan Meyer ( 2 room book ) | V10: Nagore Redin | Y10: Marie Schürmann | AA10: Konstantinos Pravitas | AE10: Dymphna Mooney | AH10: Dymphna Mooney | AI10: Angel Raymundo Bailon Ramos
A11: 9 | B11: Single Queen | C11: 1 | D11: Serena Vitaliano | G11: Burchart Nadine | L11: 1 | M11: Chen Zhan Chen | Z11: Walk in Paid 800฿ | AA11: Sean Hewston | AD11: Marta Trzonkowska (2 room book) | AG11: Jennifer Malm | AH11: Jennifer Malm | AK11: Fabiana Andreoli | AN11: 1
A12: 10 | B12: Twin Bed | C12: 1 | D12: Aleksander Cybulski 13:00 | H12: 1 | L12: De Beijer Sacha | O12: Guido Kaspers | R12: 1 | S12: Eleonora Peruzzi 10:00 AM ถึง 11:00 AM | X12: Maryanne Nguyen | AC12: 1 | AG12: Svetlana Beroggi | AI12: Paris Cochran | AM12: 1 | AN12: 1
A13: 11 | B13: Twin Bed | C13: Strong Tracy | F13: Annie Price 12:00 PM ถึง 1:00 PM | I13: Ray Emily | L13: 1 | M13: Claudia Le Gall | R13: 秀俐 李 | T13: Camilla Nunn / ต้องการห้องเงียบ | AH13: Camilla Nunn | AN13: 1
A14: 12 | B14: Single | C14: Camilla Ditz Vagner | E14: Emilie Stefan ( 2 room book ) | I14: Tracie Mankowski | M14: Taylor Tran | T14: แม่อ๊อด | X14: Lander Ortiz de Zarate Ereño | AA14: Roy Shiloh | AC14: Liliane Teunissen | AH14: 1 | AI14: 1 | AJ14: 1 | AK14: 1 | AL14: 1 | AM14: 1 | AN14: 1
A15: Suite | B15: Honeymoon | C15: MONTANA SINPRASERT | D15: Tom Barber | G15: Claudia Sinnona 14:00 | I15: Fix curtain | J15: Jacques humpich | N15: Pii Por | O15: cheriane muller | Q15: Sirichok Niamtiang | V15: Vincent de Jong | X15: Carine Spaens | AD15: NATTHARIN CHAKAVALPITAK | AF15: Johan Magnus Rydlund | AI15: 1 | AJ15: 1 | AK15: Lily Deascenti
C16: =(31*13-SUM(C17:AG20))/(31*13) -> 0.97270471 | AH16: =(28*13-SUM(AH17:BI20))/(28*13) -> 0.95604396
B17: Superiroe | C17: =C28+C34 -> 1 | D17: =D28+D34 -> 0 | E17: =E28+E34 -> 0 | F17: =F28+F34 -> 0 | G17: =G28+G34 -> 0 | H17: =H28+H34 -> 0 | I17: =I28+I34 -> 0 | J17: =J28+J34 -> 0 | ... AN17: =AN28+AN34 -> 0
B18: Deluxe Double | C18: =C26+C27+C31+C32+C33+C37 -> 0 | D18: =D26+D27+D31+D32+D33+D37 -> 0 | E18: =E26+E27+E31+E32+E33+E37 -> 0 | F18: =F26+F27+F31+F32+F33+F37 -> 0 | G18: =G26+G27+G31+G32+G33+G37 -> 0 | H18: =H26+H27+H31+H32+H33+H37 -> 0 | I18: =I26+I27+I31+I32+I33+I37 -> 0 | J18: =J26+J27+J31+J32+J33+J37 -> 0 | ... AN18: =AN26+AN27+AN31+AN32+AN33+AN37 -> 2
B19: DeluxeTwin | C19: =C29+C30+C35+C36 -> 1 | D19: =D29+D30+D35+D36 -> 0 | E19: =E29+E30+E35+E36 -> 0 | F19: =F29+F30+F35+F36 -> 0 | G19: =G29+G30+G35+G36 -> 0 | H19: =H29+H30+H35+H36 -> 1 | I19: =I29+I30+I35+I36 -> 0 | J19: =J29+J30+J35+J36 -> 0 | ... AN19: =AN29+AN30+AN35+AN36 -> 2
B20: Honeymoon Suite | C20: =C38 -> 0 | D20: =D38 -> 0 | E20: =E38 -> 0 | F20: =F38 -> 0 | G20: =G38 -> 0 | H20: =H38 -> 0 | I20: =I38 -> 0 | J20: =J38 -> 0 | ... AN20: =AN38 -> 0
C21: =SUM(C17:C20) -> 2 | D21: =SUM(D17:D20) -> 0 | E21: =SUM(E17:E20) -> 0 | F21: =SUM(F17:F20) -> 0 | G21: =SUM(G17:G20) -> 0 | H21: =SUM(H17:H20) -> 1 | I21: =SUM(I17:I20) -> 0 | J21: =SUM(J17:J20) -> 0 | ... AN21: =SUM(AN17:AN20) -> 4
J24: {=+J24+E26:E37+E26+E26:E38} -> 0
B26: 1 | C26: =IF(C3=1,1,0) -> 0 | D26: =IF(D3=1,1,0) -> 0 | E26: =IF(E3=1,1,0) -> 0 | F26: =IF(F3=1,1,0) -> 0 | G26: =IF(G3=1,1,0) -> 0 | H26: =IF(H3=1,1,0) -> 0 | I26: =IF(I3=1,1,0) -> 0 | J26: =IF(J3=1,1,0) -> 0 | ... AN26: =IF(AN3=1,1,0) -> 0
B27: 2 | C27: =IF(C4=1,1,0) -> 0 | D27: =IF(D4=1,1,0) -> 0 | E27: =IF(E4=1,1,0) -> 0 | F27: =IF(F4=1,1,0) -> 0 | G27: =IF(G4=1,1,0) -> 0 | H27: =IF(H4=1,1,0) -> 0 | I27: =IF(I4=1,1,0) -> 0 | J27: =IF(J4=1,1,0) -> 0 | ... AN27: =IF(AN4=1,1,0) -> 0
B28: 3 | C28: =IF(C5=1,1,0) -> 0 | D28: =IF(D5=1,1,0) -> 0 | E28: =IF(E5=1,1,0) -> 0 | F28: =IF(F5=1,1,0) -> 0 | G28: =IF(G5=1,1,0) -> 0 | H28: =IF(H5=1,1,0) -> 0 | I28: =IF(I5=1,1,0) -> 0 | J28: =IF(J5=1,1,0) -> 0 | ... AN28: =IF(AN5=1,1,0) -> 0
B29: 4 | C29: =IF(C6=1,1,0) -> 0 | D29: =IF(D6=1,1,0) -> 0 | E29: =IF(E6=1,1,0) -> 0 | F29: =IF(F6=1,1,0) -> 0 | G29: =IF(G6=1,1,0) -> 0 | H29: =IF(H6=1,1,0) -> 0 | I29: =IF(I6=1,1,0) -> 0 | J29: =IF(J6=1,1,0) -> 0 | ... AN29: =IF(AN6=1,1,0) -> 0
B30: 5 | C30: =IF(C7=1,1,0) -> 0 | D30: =IF(D7=1,1,0) -> 0 | E30: =IF(E7=1,1,0) -> 0 | F30: =IF(F7=1,1,0) -> 0 | G30: =IF(G7=1,1,0) -> 0 | H30: =IF(H7=1,1,0) -> 0 | I30: =IF(I7=1,1,0) -> 0 | J30: =IF(J7=1,1,0) -> 0 | ... AN30: =IF(AN7=1,1,0) -> 0
B31: 6 | C31: =IF(C8=1,1,0) -> 0 | D31: =IF(D8=1,1,0) -> 0 | E31: =IF(E8=1,1,0) -> 0 | F31: =IF(F8=1,1,0) -> 0 | G31: =IF(G8=1,1,0) -> 0 | H31: =IF(H8=1,1,0) -> 0 | I31: =IF(I8=1,1,0) -> 0 | J31: =IF(J8=1,1,0) -> 0 | ... AN31: =IF(AN8=1,1,0) -> 1
B32: 7 | C32: =IF(C9=1,1,0) -> 0 | D32: =IF(D9=1,1,0) -> 0 | E32: =IF(E9=1,1,0) -> 0 | F32: =IF(F9=1,1,0) -> 0 | G32: =IF(G9=1,1,0) -> 0 | H32: =IF(H9=1,1,0) -> 0 | I32: =IF(I9=1,1,0) -> 0 | J32: =IF(J9=1,1,0) -> 0 | ... AN32: =IF(AN9=1,1,0) -> 0
B33: 8 | C33: =IF(C10=1,1,0) -> 0 | D33: =IF(D10=1,1,0) -> 0 | E33: =IF(E10=1,1,0) -> 0 | F33: =IF(F10=1,1,0) -> 0 | G33: =IF(G10=1,1,0) -> 0 | H33: =IF(H10=1,1,0) -> 0 | I33: =IF(I10=1,1,0) -> 0 | J33: =IF(J10=1,1,0) -> 0 | ... AN33: =IF(AN10=1,1,0) -> 0
B34: 9 | C34: =IF(C11=1,1,0) -> 1 | D34: =IF(D11=1,1,0) -> 0 | E34: =IF(E11=1,1,0) -> 0 | F34: =IF(F11=1,1,0) -> 0 | G34: =IF(G11=1,1,0) -> 0 | H34: =IF(H11=1,1,0) -> 0 | I34: =IF(I11=1,1,0) -> 0 | J34: =IF(J11=1,1,0) -> 0 | ... AG34: =IF(AG11=1,1,0) -> 0 | AH34: =IF('Jan2026'!BL11=1,1,0) -> 0 | AI34: =IF('Jan2026'!BM11=1,1,0) -> 0 | AJ34: =IF('Jan2026'!BN11=1,1,0) -> 0 | AK34: =IF('Jan2026'!BO11=1,1,0) -> 0 | AL34: =IF('Jan2026'!BP11=1,1,0) -> 0 | AM34: =IF('Jan2026'!BQ11=1,1,0) -> 0 | AN34: =IF('Jan2026'!BR11=1,1,0) -> 0
B35: 10 | C35: =IF(C12=1,1,0) -> 1 | D35: =IF(D12=1,1,0) -> 0 | E35: =IF(E12=1,1,0) -> 0 | F35: =IF(F12=1,1,0) -> 0 | G35: =IF(G12=1,1,0) -> 0 | H35: =IF(H12=1,1,0) -> 1 | I35: =IF(I12=1,1,0) -> 0 | J35: =IF(J12=1,1,0) -> 0 | ... AN35: =IF(AN12=1,1,0) -> 1
B36: 11 | C36: =IF(C13=1,1,0) -> 0 | D36: =IF(D13=1,1,0) -> 0 | E36: =IF(E13=1,1,0) -> 0 | F36: =IF(F13=1,1,0) -> 0 | G36: =IF(G13=1,1,0) -> 0 | H36: =IF(H13=1,1,0) -> 0 | I36: =IF(I13=1,1,0) -> 0 | J36: =IF(J13=1,1,0) -> 0 | ... AN36: =IF(AN13=1,1,0) -> 1
B37: 12 | C37: =IF(C14=1,1,0) -> 0 | D37: =IF(D14=1,1,0) -> 0 | E37: =IF(E14=1,1,0) -> 0 | F37: =IF(F14=1,1,0) -> 0 | G37: =IF(G14=1,1,0) -> 0 | H37: =IF(H14=1,1,0) -> 0 | I37: =IF(I14=1,1,0) -> 0 | J37: =IF(J14=1,1,0) -> 0 | ... AN37: =IF(AN14=1,1,0) -> 1
B38: Suite | C38: =IF(C15=1,1,0) -> 0 | D38: =IF(D15=1,1,0) -> 0 | E38: =IF(E15=1,1,0) -> 0 | F38: =IF(F15=1,1,0) -> 0 | G38: =IF(G15=1,1,0) -> 0 | H38: =IF(H15=1,1,0) -> 0 | I38: =IF(I15=1,1,0) -> 0 | J38: =IF(J15=1,1,0) -> 0 | ... AN38: =IF(AN15=1,1,0) -> 0

Sheet Feb2026
A1: Room | B1: Type | C1: 1 | D1: 2 | E1: 3 | F1: 4 | G1: 5 | H1: 6 | I1: 7 | J1: 8 | K1: 9 | L1: 10 | M1: 11 | N1: 12 | O1: 13 | P1: 14 | Q1: 15 | R1: 16 | S1: 17 | T1: 18 | U1: 19 | V1: 20 | W1: 21 | X1: 22 | Y1: 23 | Z1: 24 | AA1: 25 | AB1: 26 | AC1: 27 | AD1: 28
C2: Sun | D2: Mon | E2: Tue | F2: Wed | G2: Thu | H2: Fri | I2: Sat | J2: Sun | K2: Mon | L2: Tue | M2: Wed | N2: Thu | O2: Fri | P2: Sat | Q2: Sun | R2: Mon | S2: Tue | T2: Wed | U2: Thu | V2: Fri | W2: Sat | X2: Sun | Y2: Mon | Z2: Tue | AA2: Wed | AB2: Thu | AC2: Fri | AD2: Sat
A3: 1 | B3: Single | C3: Anna Anguera Reverté | D3: Romane Million | G3: Robert Lislois | K3: Beatrice Grist | O3: Lehtonen Mika | R3: Muriel Ferzandi | U3: Anne-Laure Vila | X3: Jun Lim DD x4, DT x1 | AA3: Stijn Berendsen | AD3: 1
A4: 2 | B4: Single | C4: richard kelly | G4: Braun Christina | O4: 1 | P4: Domenico Magnante | S4: Eimear Kirk | U4: Eliana Felice จำนวน 2 ห้อง SD->DD | AA4: Yue Ding
A5: 3 | B5: Single Queen | C5: Michelle Huang | D5: Adelina Dopico López | G5: Mattea Grech | J5: Ana Vanesa Gonzalez | M5: qin zhang | O5: qin zhang | R5: 1 | S5: Sabine Schmitz (2 room book 3&9) | U5: Eliana Felice จำนวน 2 ห้อง | X5: Ryan Barlow | Z5: Evelin Dianela Cravero | AD5: WEN-CHUN SHIH
A6: 4 | B6: Twin Bed | C6: Laura Munoz | D6: JANE SELIA DOS REIS COIMBRA | G6: Ramanjit Kaur | K6: addison gillespie | O6: olivia rodd | S6: Warren Gardner | V6: Patrick Fizpatrick | X6: Jun Lim DD x4, DT x1 | AA6: Benco Tjep | AC6: Georgette van Loon
A7: 5 | B7: Twin Bed | C7: shirel azizi | E7: Deborah Young | J7: Joanna Sokalla | N7: Gloria Fok | Q7: Carolin Buss 18:30 | S7: Extend 1 more night Paid already | T7: Elisabeth Lai | Y7: check out 6 pm (500฿) | Z7: Julia Targońska | AC7: de vries hugo
A8: 6 | B8: Single | C8: youcyuan lin | D8: 1 | E8: Ambrosio James | I8: 1 | N8: Bastianelli Giulia | Q8: Lilli Soernes | T8: Rayzia David / Check In 2:00Am of 19/2 and Need room with window | X8: Jun Lim DD x4, DT x1 | AA8: Lucy Walker
A9: 7 | B9: Single | C9: Florian Pöppelmann | F9: Annika Ramesh | I9: Helen Kuswik | M9: Cristina Pérez Pampano | P9: Jonna Skold | S9: 1 | T9: Alessia Scarpa | W9: 1 | AA9: 1 | AB9: Marcin Kotlarz
A10: 8 | B10: Single | C10: Dymphna Mooney | D10: Angel Raymundo Bailon Ramos | G10: Ghisiaine Gralepois | K10: Félix Bayart | R10: 1 | S10: Maike Reuss | V10: Yannick Ullisch | AA10: 1
A11: 9 | B11: Single Queen | C11: Jennifer Malm | F11: Fabiana Andreoli | I11: Elizabeth Ozolins | K11: Gabriel Lima de Melo | O11: Hannah Sullivan | R11: 1 | S11: Sabine Schmitz (2 room book 3&9) | U11: 1 | V11: christina AIRBNB | Z11: / | AA11: Hien BUI | AD11: YeonMi Baek
A12: 10 | B12: Twin Bed | C12: 1 | D12: Paris Cochran | H12: Daniël Jansen | L12: 1 | M12: 1 | N12: Rebecca Dale | R12: Joshua Nelson | V12: Joanna Zając | Y12: 1 | Z12: Cédric Vandenbussche
A13: 11 | B13: Twin Bed | C13: Camilla Nunn | I13: Calvin Janson | L13: Justin Huber / 2:00 PM- 3:00 PM | P13: emmanuel dejace | S13: Emily Stockum | V13: sefton greene | X13: Edina Vilmányi | AB13: SHUYING XU
A14: 12 | B14: Single | C14: 1 | D14: lahaye dominique | L14: 1 | M14: Nina Dawe | P14: Breea Meyer | T14: Jan Malchar | W14: 1 | X14: Erica Ebner SD->DD | AA14: Richard Blanchfield | AC14: Katherine Sierra
A15: Suite | B15: Honeymoon | C15: Johan Magnus Rydlund | D15: Extend 1,200x2 (Paid 2400฿ already) | F15: Lily Deascenti | J15: Alexandra Fillion | M15: Extend 1 night | N15: Simona Iurlaro | Q15: 1 | R15: Jane Bannister Grech | U15: Shamai Ziv | Y15: Mathys Depraz | AB15: Paweł Banaszczyk
C16: =(28*13-SUM(C17:AD20))/(28*13) -> 0.9478022 | D16: 2400 | H16: Margo AIRBNB | M16: 900 | S16: 900 | Y16: 500
B17: Superiroe | C17: =C28+C34 -> 0 | D17: =D28+D34 -> 0 | E17: =E28+E34 -> 0 | F17: =F28+F34 -> 0 | G17: =G28+G34 -> 0 | H17: =H28+H34 -> 0 | I17: =I28+I34 -> 0 | J17: =J28+J34 -> 1 | ... AD17: =AD28+AD34 -> 0
B18: Deluxe Double | C18: =C26+C27+C31+C32+C33+C37 -> 1 | D18: =D26+D27+D31+D32+D33+D37 -> 1 | E18: =E26+E27+E31+E32+E33+E37 -> 0 | F18: =F26+F27+F31+F32+F33+F37 -> 0 | G18: =G26+G27+G31+G32+G33+G37 -> 0 | H18: =H26+H27+H31+H32+H33+H37 -> 0 | I18: =I26+I27+I31+I32+I33+I37 -> 1 | J18: =J26+J27+J31+J32+J33+J37 -> 0 | ... AD18: =AD26+AD27+AD31+AD32+AD33+AD37 -> 1
B19: DeluxeTwin | C19: =C29+C30+C35+C36 -> 1 | D19: =D29+D30+D35+D36 -> 0 | E19: =E29+E30+E35+E36 -> 0 | F19: =F29+F30+F35+F36 -> 0 | G19: =G29+G30+G35+G36 -> 0 | H19: =H29+H30+H35+H36 -> 0 | I19: =I29+I30+I35+I36 -> 0 | J19: =J29+J30+J35+J36 -> 0 | ... AD19: =AD29+AD30+AD35+AD36 -> 0
B20: Honeymoon Suite | C20: =C38 -> 0 | D20: =D38 -> 0 | E20: =E38 -> 0 | F20: =F38 -> 0 | G20: =G38 -> 0 | H20: =H38 -> 0 | I20: =I38 -> 0 | J20: =J38 -> 0 | ... AD20: =AD38 -> 0
C21: =SUM(C17:C20) -> 2 | D21: =SUM(D17:D20) -> 1 | E21: =SUM(E17:E20) -> 0 | F21: =SUM(F17:F20) -> 0 | G21: =SUM(G17:G20) -> 0 | H21: =SUM(H17:H20) -> 0 | I21: =SUM(I17:I20) -> 1 | J21: =SUM(J17:J20) -> 1 | ... AD21: =SUM(AD17:AD20) -> 1
B26: 1 | C26: =IF(C3=1,1,0) -> 0 | D26: =IF(D3=1,1,0) -> 0 | E26: =IF(E3=1,1,0) -> 0 | F26: =IF(F3=1,1,0) -> 0 | G26: =IF(G3=1,1,0) -> 0 | H26: =IF(H3=1,1,0) -> 0 | I26: =IF(I3=1,1,0) -> 0 | J26: =IF(J3=1,1,0) -> 0 | ... AD26: =IF(AD3=1,1,0) -> 1
B27: 2 | C27: =IF(C4=1,1,0) -> 0 | D27: =IF(D4=1,1,0) -> 0 | E27: =IF(E4=1,1,0) -> 0 | F27: =IF(F4=1,1,0) -> 0 | G27: =IF(G4=1,1,0) -> 0 | H27: =IF(H4=1,1,0) -> 0 | I27: =IF(I4=1,1,0) -> 0 | J27: =IF(J4=1,1,0) -> 0 | ... AD27: =IF(AD4=1,1,0) -> 0
B28: 3 | C28: =IF(C5=1,1,0) -> 0 | D28: =IF(D5=1,1,0) -> 0 | E28: =IF(E5=1,1,0) -> 0 | F28: =IF(F5=1,1,0) -> 0 | G28: =IF(G5=1,1,0) -> 0 | H28: =IF(H5=1,1,0) -> 0 | I28: =IF(I5=1,1,0) -> 0 | J28: =IF(J5=1,1,0) -> 0 | ... AD28: =IF(AD5=1,1,0) -> 0
B29: 4 | C29: =IF(C6=1,1,0) -> 0 | D29: =IF(D6=1,1,0) -> 0 | E29: =IF(E6=1,1,0) -> 0 | F29: =IF(F6=1,1,0) -> 0 | G29: =IF(G6=1,1,0) -> 0 | H29: =IF(H6=1,1,0) -> 0 | I29: =IF(I6=1,1,0) -> 0 | J29: =IF(J6=1,1,0) -> 0 | ... AD29: =IF(AD6=1,1,0) -> 0
B30: 5 | C30: =IF(C7=1,1,0) -> 0 | D30: =IF(D7=1,1,0) -> 0 | E30: =IF(E7=1,1,0) -> 0 | F30: =IF(F7=1,1,0) -> 0 | G30: =IF(G7=1,1,0) -> 0 | H30: =IF(H7=1,1,0) -> 0 | I30: =IF(I7=1,1,0) -> 0 | J30: =IF(J7=1,1,0) -> 0 | ... AD30: =IF(AD7=1,1,0) -> 0
B31: 6 | C31: =IF(C8=1,1,0) -> 0 | D31: =IF(D8=1,1,0) -> 1 | E31: =IF(E8=1,1,0) -> 0 | F31: =IF(F8=1,1,0) -> 0 | G31: =IF(G8=1,1,0) -> 0 | H31: =IF(H8=1,1,0) -> 0 | I31: =IF(I8=1,1,0) -> 1 | J31: =IF(J8=1,1,0) -> 0 | ... AD31: =IF(AD8=1,1,0) -> 0
B32: 7 | C32: =IF(C9=1,1,0) -> 0 | D32: =IF(D9=1,1,0) -> 0 | E32: =IF(E9=1,1,0) -> 0 | F32: =IF(F9=1,1,0) -> 0 | G32: =IF(G9=1,1,0) -> 0 | H32: =IF(H9=1,1,0) -> 0 | I32: =IF(I9=1,1,0) -> 0 | J32: =IF(J9=1,1,0) -> 0 | ... AD32: =IF(AD9=1,1,0) -> 0
B33: 8 | C33: =IF(C10=1,1,0) -> 0 | D33: =IF(D10=1,1,0) -> 0 | E33: =IF(E10=1,1,0) -> 0 | F33: =IF(F10=1,1,0) -> 0 | G33: =IF(G10=1,1,0) -> 0 | H33: =IF(H10=1,1,0) -> 0 | I33: =IF(I10=1,1,0) -> 0 | J33: =IF(J10=1,1,0) -> 0 | ... AD33: =IF(AD10=1,1,0) -> 0
B34: 9 | C34: =IF('Jan2026'!AG11=1,1,0) -> 0 | D34: =IF('Jan2026'!AH11=1,1,0) -> 0 | E34: =IF('Jan2026'!AI11=1,1,0) -> 0 | F34: =IF('Jan2026'!AJ11=1,1,0) -> 0 | G34: =IF('Jan2026'!AK11=1,1,0) -> 0 | H34: =IF('Jan2026'!AL11=1,1,0) -> 0 | I34: =IF('Jan2026'!AM11=1,1,0) -> 0 | J34: =IF('Jan2026'!AN11=1,1,0) -> 1 | ... AD34: =IF('Jan2026'!BH11=1,1,0) -> 0
B35: 10 | C35: =IF(C12=1,1,0) -> 1 | D35: =IF(D12=1,1,0) -> 0 | E35: =IF(E12=1,1,0) -> 0 | F35: =IF(F12=1,1,0) -> 0 | G35: =IF(G12=1,1,0) -> 0 | H35: =IF(H12=1,1,0) -> 0 | I35: =IF(I12=1,1,0) -> 0 | J35: =IF(J12=1,1,0) -> 0 | ... AD35: =IF(AD12=1,1,0) -> 0
B36: 11 | C36: =IF(C13=1,1,0) -> 0 | D36: =IF(D13=1,1,0) -> 0 | E36: =IF(E13=1,1,0) -> 0 | F36: =IF(F13=1,1,0) -> 0 | G36: =IF(G13=1,1,0) -> 0 | H36: =IF(H13=1,1,0) -> 0 | I36: =IF(I13=1,1,0) -> 0 | J36: =IF(J13=1,1,0) -> 0 | ... AD36: =IF(AD13=1,1,0) -> 0
B37: 12 | C37: =IF(C14=1,1,0) -> 1 | D37: =IF(D14=1,1,0) -> 0 | E37: =IF(E14=1,1,0) -> 0 | F37: =IF(F14=1,1,0) -> 0 | G37: =IF(G14=1,1,0) -> 0 | H37: =IF(H14=1,1,0) -> 0 | I37: =IF(I14=1,1,0) -> 0 | J37: =IF(J14=1,1,0) -> 0 | ... AD37: =IF(AD14=1,1,0) -> 0
B38: Suite | C38: =IF(C15=1,1,0) -> 0 | D38: =IF(D15=1,1,0) -> 0 | E38: =IF(E15=1,1,0) -> 0 | F38: =IF(F15=1,1,0) -> 0 | G38: =IF(G15=1,1,0) -> 0 | H38: =IF(H15=1,1,0) -> 0 | I38: =IF(I15=1,1,0) -> 0 | J38: =IF(J15=1,1,0) -> 0 | ... AD38: =IF(AD15=1,1,0) -> 0

Sheet Mar2026
A1: Room | B1: Type | C1: 1 | D1: 2 | E1: 3 | F1: 4 | G1: 5 | H1: 6 | I1: 7 | J1: 8 | K1: 9 | L1: 10 | M1: 11 | N1: 12 | O1: 13 | P1: 14 | Q1: 15 | R1: 16 | S1: 17 | T1: 18 | U1: 19 | V1: 20 | W1: 21 | X1: 22 | Y1: 23 | Z1: 24 | AA1: 25 | AB1: 26 | AC1: 27 | AD1: 28 | AE1: 29 | AF1: 30 | AG1: 31
C2: Sun | D2: Mon | E2: Tue | F2: Wed | G2: Thu | H2: Fri | I2: Sat | J2: Sun | K2: Mon | L2: Tue | M2: Wed | N2: Thu | O2: Fri | P2: Sat | Q2: Sun | R2: Mon | S2: Tue | T2: Wed | U2: Thu | V2: Fri | W2: Sat | X2: Sun | Y2: Mon | Z2: Tue | AA2: Wed | AB2: Thu | AC2: Fri | AD2: Sat | AE2: Sun | AF2: Mon | AG2: Tue
A3: 1 | B3: Single | C3: Barbara Heffernan | H3: Edouard Bertrand | M3: Gold Stuart | P3: 1 | Q3: Irene Peral Martin | T3: Paul Staite | W3: Lisa Karol | Z3: Hendrik willem Peters | AC3: Extend 2-nights (Paid 1600) | AE3: Natalia Zapata
A4: 2 | B4: Single | C4: Yue Ding | D4: Cheuk Yin Ng | G4: 1 | H4: 1 | I4: Laura healy | N4: 1 | O4: wydenes Brandee | R4: 1 | S4: Anja Raygrotzki | X4: Hyacinth Liesdek | AC4: 1 | AD4: ANTONIA GLYNIADAKI
A5: 3 | B5: Single Queen | C5: WEN-CHUN SHIH | H5: Chiesa Sandra | J5: 1 | K5: Colby Butchereit | O5: Iiris Korpela | S5: Elif Simsir | W5: 1 | X5: Kamenow Milos | AA5: Maisy Blair | AD5: Yi Chin Hsu
A6: 4 | B6: Twin Bed | C6: Georgette van Loon | F6: Chia-Yu Hsu | J6: Fatimah Rahima Jingona 1675017172 (Requed Twin Bed) | P6: 1 | Q6: Gian Nadig | U6: Piotr Gembicki | X6: Kam Afzal | AD6: YUN JIE LI
A7: 5 | B7: Twin Bed | C7: de vries hugo | D7: Stefanie Wanner | G7: 1 | H7: 1 | I7: MIN JIA CHAN | M7: 1 | N7: 1 | O7: Tomohiko Tabuchi | R7: Kiell Skibba | W7: Maja Alina Kretschmer (make the bed to King Size) | AA7: 1 | AB7: Jaśmina Błażewicz [make the bed to king size] | AE7: 1 | AF7: 1 | AG7: 1
A8: 6 | B8: Single | C8: Andrew Billington | L8: 1 | M8: Žan Travnikar | Q8: Thomas Schmid 629344479 | W8: 1 | X8: 1 | Y8: Jennifer Sievers | AE8: Pedro Santos
A9: 7 | B9: Single | C9: Inna Chayka | E9: Michela Catapano | H9: Iiris Korpela | O9: javier moreno silva | R9: Blerina SADIKU | V9: Erskine Matthew | X9: Christian Fernandez | AB9: Yin Yin Phyu | AE9: 1 | AF9: Alejandra Jadue
A10: 8 | B10: Single | C10: L Jones | F10: Lucia Hrompová 629928211 | J10: 1 | K10: 1 | L10: 1 | M10: Mark Westra 2 rooms 1SD+1DD | P10: Mizgin Turunc | T10: Tania Ingrid Hernandez 1,000 | U10: Manon Lecussan | Z10: 1 | AA10: Yaoyao Jiao | AD10: Alexander Walcher
A11: 9 | B11: Single Queen | C11: YeonMi Baek | G11: 1 | H11: 1 | I11: Kristýna Sluková | L11: 1 | M11: Mark Westra 2 rooms 1SD+1DD | P11: Tania Ingrid Hernandez | S11: Francesco Piermartini | V11: Siulina Mega | Y11: Mabel Ziman | AC11: Sunavska Barbora | AG11: Claudio Helmer
A12: 10 | B12: Twin Bed | C12: Cédric Vandenbussche | D12: Chiesa Sandra | G12: Rachel Lawrence | J12: 1 | K12: darshan patel | N12: Matas Rimka | S12: Melissa Commandeur | V12: Bae Huejin | Y12: Blerion Muco 632709115 | AC12: 1 | AD12: 1 | AE12: 1 | AF12: 1 | AG12: 1
A13: 11 | B13: Twin Bed | C13: Tom Wiese (Make to King Bed) | H13: Michael Suhlunegger | L13: Extend 1,000 | M13: Eva Huizinga (Change Check in date from 10->11) | AB13: Shannan Wittshipe | AG13: Arthur Lyons
A14: 12 | B14: Single | C14: Katherine Sierra | D14: 1 | E14: 1 | F14: Diana Albu | I14: Bryoni Ashton | L14: Adrian Labus | R14: Timothy Rek | T14: Bianca Sarina Neurohr | W14: 1 | X14: Julia Sandelin | AA14: 1 | AB14: 1 | AC14: Lva Pavlovic | AG14: Tamera hutcherson (9:00-10:00 Am)
A15: Suite | B15: Honeymoon | C15: Nunzio Sciacca | F15: 1 | G15: 1 | H15: Johanna Osterwind | K15: Extand 1,200 | L15: Javier Abajo | P15: 1 | Q15: Wing Yan Sum | T15: Sumaira Zaheer | W15: 1 | X15: 1 | Y15: Jagoda Wall | AC15: 1 | AD15: Francisco Javier Gonzalez Diaz
C16: =(31*13-SUM(C17:AG20))/(31*13) -> 0.88833747
B17: Superiroe | C17: =C28+C34 -> 0 | D17: =D28+D34 -> 0 | E17: =E28+E34 -> 0 | F17: =F28+F34 -> 0 | G17: =G28+G34 -> 1 | H17: =H28+H34 -> 1 | I17: =I28+I34 -> 0 | J17: =J28+J34 -> 1 | ... AG17: =AG28+AG34 -> 0
B18: Deluxe Double | C18: =C26+C27+C31+C32+C33+C37 -> 0 | D18: =D26+D27+D31+D32+D33+D37 -> 1 | E18: =E26+E27+E31+E32+E33+E37 -> 1 | F18: =F26+F27+F31+F32+F33+F37 -> 0 | G18: =G26+G27+G31+G32+G33+G37 -> 1 | H18: =H26+H27+H31+H32+H33+H37 -> 1 | I18: =I26+I27+I31+I32+I33+I37 -> 0 | J18: =J26+J27+J31+J32+J33+J37 -> 1 | ... AG18: =AG26+AG27+AG31+AG32+AG33+AG37 -> 0
B19: DeluxeTwin | C19: =C29+C30+C35+C36 -> 0 | D19: =D29+D30+D35+D36 -> 0 | E19: =E29+E30+E35+E36 -> 0 | F19: =F29+F30+F35+F36 -> 0 | G19: =G29+G30+G35+G36 -> 1 | H19: =H29+H30+H35+H36 -> 1 | I19: =I29+I30+I35+I36 -> 0 | J19: =J29+J30+J35+J36 -> 1 | ... AG19: =AG29+AG30+AG35+AG36 -> 2
B20: Honeymoon Suite | C20: =C38 -> 0 | D20: =D38 -> 0 | E20: =E38 -> 0 | F20: =F38 -> 1 | G20: =G38 -> 1 | H20: =H38 -> 0 | I20: =I38 -> 0 | J20: =J38 -> 0 | ... AG20: =AG38 -> 0
C21: =SUM(C17:C20) -> 0 | D21: =SUM(D17:D20) -> 1 | E21: =SUM(E17:E20) -> 1 | F21: =SUM(F17:F20) -> 1 | G21: =SUM(G17:G20) -> 4 | H21: =SUM(H17:H20) -> 3 | I21: =SUM(I17:I20) -> 0 | J21: =SUM(J17:J20) -> 3 | ... AG21: =SUM(AG17:AG20) -> 2
B26: 1 | C26: =IF(C3=1,1,0) -> 0 | D26: =IF(D3=1,1,0) -> 0 | E26: =IF(E3=1,1,0) -> 0 | F26: =IF(F3=1,1,0) -> 0 | G26: =IF(G3=1,1,0) -> 0 | H26: =IF(H3=1,1,0) -> 0 | I26: =IF(I3=1,1,0) -> 0 | J26: =IF(J3=1,1,0) -> 0 | ... AG26: =IF(AG3=1,1,0) -> 0
B27: 2 | C27: =IF(C4=1,1,0) -> 0 | D27: =IF(D4=1,1,0) -> 0 | E27: =IF(E4=1,1,0) -> 0 | F27: =IF(F4=1,1,0) -> 0 | G27: =IF(G4=1,1,0) -> 1 | H27: =IF(H4=1,1,0) -> 1 | I27: =IF(I4=1,1,0) -> 0 | J27: =IF(J4=1,1,0) -> 0 | ... AG27: =IF(AG4=1,1,0) -> 0
B28: 3 | C28: =IF(C5=1,1,0) -> 0 | D28: =IF(D5=1,1,0) -> 0 | E28: =IF(E5=1,1,0) -> 0 | F28: =IF(F5=1,1,0) -> 0 | G28: =IF(G5=1,1,0) -> 0 | H28: =IF(H5=1,1,0) -> 0 | I28: =IF(I5=1,1,0) -> 0 | J28: =IF(J5=1,1,0) -> 1 | ... AG28: =IF(AG5=1,1,0) -> 0
B29: 4 | C29: =IF(C6=1,1,0) -> 0 | D29: =IF(D6=1,1,0) -> 0 | E29: =IF(E6=1,1,0) -> 0 | F29: =IF(F6=1,1,0) -> 0 | G29: =IF(G6=1,1,0) -> 0 | H29: =IF(H6=1,1,0) -> 0 | I29: =IF(I6=1,1,0) -> 0 | J29: =IF(J6=1,1,0) -> 0 | ... AG29: =IF(AG6=1,1,0) -> 0
B30: 5 | C30: =IF(C7=1,1,0) -> 0 | D30: =IF(D7=1,1,0) -> 0 | E30: =IF(E7=1,1,0) -> 0 | F30: =IF(F7=1,1,0) -> 0 | G30: =IF(G7=1,1,0) -> 1 | H30: =IF(H7=1,1,0) -> 1 | I30: =IF(I7=1,1,0) -> 0 | J30: =IF(J7=1,1,0) -> 0 | ... AG30: =IF(AG7=1,1,0) -> 1
B31: 6 | C31: =IF(C8=1,1,0) -> 0 | D31: =IF(D8=1,1,0) -> 0 | E31: =IF(E8=1,1,0) -> 0 | F31: =IF(F8=1,1,0) -> 0 | G31: =IF(G8=1,1,0) -> 0 | H31: =IF(H8=1,1,0) -> 0 | I31: =IF(I8=1,1,0) -> 0 | J31: =IF(J8=1,1,0) -> 0 | ... AG31: =IF(AG8=1,1,0) -> 0
B32: 7 | C32: =IF(C9=1,1,0) -> 0 | D32: =IF(D9=1,1,0) -> 0 | E32: =IF(E9=1,1,0) -> 0 | F32: =IF(F9=1,1,0) -> 0 | G32: =IF(G9=1,1,0) -> 0 | H32: =IF(H9=1,1,0) -> 0 | I32: =IF(I9=1,1,0) -> 0 | J32: =IF(J9=1,1,0) -> 0 | ... AG32: =IF(AG9=1,1,0) -> 0
B33: 8 | C33: =IF(C10=1,1,0) -> 0 | D33: =IF(D10=1,1,0) -> 0 | E33: =IF(E10=1,1,0) -> 0 | F33: =IF(F10=1,1,0) -> 0 | G33: =IF(G10=1,1,0) -> 0 | H33: =IF(H10=1,1,0) -> 0 | I33: =IF(I10=1,1,0) -> 0 | J33: =IF(J10=1,1,0) -> 1 | ... AG33: =IF(AG10=1,1,0) -> 0
B34: 9 | C34: =IF(C11=1,1,0) -> 0 | D34: =IF(D11=1,1,0) -> 0 | E34: =IF(E11=1,1,0) -> 0 | F34: =IF(F11=1,1,0) -> 0 | G34: =IF(G11=1,1,0) -> 1 | H34: =IF(H11=1,1,0) -> 1 | I34: =IF(I11=1,1,0) -> 0 | J34: =IF(J11=1,1,0) -> 0 | ... AG34: =IF(AG11=1,1,0) -> 0
B35: 10 | C35: =IF(C12=1,1,0) -> 0 | D35: =IF(D12=1,1,0) -> 0 | E35: =IF(E12=1,1,0) -> 0 | F35: =IF(F12=1,1,0) -> 0 | G35: =IF(G12=1,1,0) -> 0 | H35: =IF(H12=1,1,0) -> 0 | I35: =IF(I12=1,1,0) -> 0 | J35: =IF(J12=1,1,0) -> 1 | ... AG35: =IF(AG12=1,1,0) -> 1
B36: 11 | C36: =IF(C13=1,1,0) -> 0 | D36: =IF(D13=1,1,0) -> 0 | E36: =IF(E13=1,1,0) -> 0 | F36: =IF(F13=1,1,0) -> 0 | G36: =IF(G13=1,1,0) -> 0 | H36: =IF(H13=1,1,0) -> 0 | I36: =IF(I13=1,1,0) -> 0 | J36: =IF(J13=1,1,0) -> 0 | ... AG36: =IF(AG13=1,1,0) -> 0
B37: 12 | C37: =IF(C14=1,1,0) -> 0 | D37: =IF(D14=1,1,0) -> 1 | E37: =IF(E14=1,1,0) -> 1 | F37: =IF(F14=1,1,0) -> 0 | G37: =IF(G14=1,1,0) -> 0 | H37: =IF(H14=1,1,0) -> 0 | I37: =IF(I14=1,1,0) -> 0 | J37: =IF(J14=1,1,0) -> 0 | ... AG37: =IF(AG14=1,1,0) -> 0
B38: Suite | C38: =IF(C15=1,1,0) -> 0 | D38: =IF(D15=1,1,0) -> 0 | E38: =IF(E15=1,1,0) -> 0 | F38: =IF(F15=1,1,0) -> 1 | G38: =IF(G15=1,1,0) -> 1 | H38: =IF(H15=1,1,0) -> 0 | I38: =IF(I15=1,1,0) -> 0 | J38: =IF(J15=1,1,0) -> 0 | ... AG38: =IF(AG15=1,1,0) -> 0

Sheet Apr2026
A1: Room | B1: Type | C1: 1 | D1: 2 | E1: 3 | F1: 4 | G1: 5 | H1: 6 | I1: 7 | J1: 8 | K1: 9 | L1: 10 | M1: 11 | N1: 12 | O1: 13 | P1: 14 | Q1: 15 | R1: 16 | S1: 17 | T1: 18 | U1: 19 | V1: 20 | W1: 21 | X1: 22 | Y1: 23 | Z1: 24 | AA1: 25 | AB1: 26 | AC1: 27 | AD1: 28 | AE1: 29 | AF1: 30
C2: Wed | D2: Thu | E2: Fri | F2: Sat | G2: Sun | H2: Mon | I2: Tue | J2: Wed | K2: Thu | L2: Fri | M2: Sat | N2: Sun | O2: Mon | P2: Tue | Q2: Wed | R2: Thu | S2: Fri | T2: Sat | U2: Sun | V2: Mon | W2: Tue | X2: Wed | Y2: Thu | Z2: Fri | AA2: Sat | AB2: Sun | AC2: Mon | AD2: Tue | AE2: Wed | AF2: Thu
A3: 1 | B3: Single | C3: 1 | D3: Turley Kyle | I3: Stefan Whaley | N3: Idol Cafe Pii Dao 800/night | R3: Emily Stewart | U3: 1 | V3: Chris Maudlin | Y3: 1 | Z3: 1 | AA3: 1 | AB3: 1 | AC3: Barbara Fernandez-Gonalez | AF3: 1
A4: 2 | B4: Single | C4: 1 | D4: Julia Fischer | I4: 1 | J4: 1. Ryan Burnett ( 2 rooms ) | M4: 1 | R4: 1 | S4: 1 | T4: David Kühn | W4: 1 | X4: 1 | Y4: 1 | Z4: Lisa Minners | AD4: Janto Groeneveld
A5: 3 | B5: Single Queen | C5: Yi Chin Hsu | F5: Francesco Mundi | J5: 2. Ryan Burnett ( 2 rooms ) | M5: Yue Jia Xi | P5: Lucas 800/night Paid | T5: Domenik Koldringer (19:00-20:00) | X5: 1 | Y5: Marie Schneider | AB5: 1 | AC5: 1 | AD5: Taylor Richards
A6: 4 | B6: Twin Bed | C6: 1 | D6: 1 | E6: 1 | F6: 1 | G6: 1 | H6: 1 | I6: Lixueyan Li | M6: Anuchit Bremner | P6: 1 | Q6: Delfina Tamagnini | T6: 1 | U6: 1 | V6: 1 | W6: 1 | X6: 1 | Y6: 1 | Z6: 1 | AA6: 1 | AB6: 1 | AC6: 1 | AD6: 1 | AE6: 1 | AF6: yiyian liang
A7: 5 | B7: Twin Bed | C7: 1 | D7: 1 | E7: 1 | F7: 1 | G7: Laura Antoniles Miguel | J7: 1 | K7: 1 | L7: Tsai Yu Cheng | P7: Arrive Before 1 Day Paid 1,100 THB | Q7: Jasmine Daniels 10:00 - 11:00 | T7: 1 | U7: 1 | V7: 1 | W7: 1 | X7: 1 | Y7: 1 | Z7: 1 | AA7: 1 | AB7: 1 | AC7: 1 | AD7: 1 | AE7: 1 | AF7: Agnes Romagny
A8: 6 | B8: Single | C8: 1 | D8: 1 | E8: 1 | F8: Pii Dao 800 | G8: Magnus Valentin Schneider | K8: Clara Filippini | N8: 1 | O8: Lucas 1,000 /night Paid | R8: 1 | S8: 1 | T8: Matthias Gruen | W8: 1 | X8: Nina Labao | AE8: Warren Fouemena
A9: 7 | B9: Single | C9: Alejandra Jadue | D9: Maria Lbis Perez del Olmo | J9: Joseph Philip Warriner | M9: Marta Bellerín | P9: 1 | Q9: GARY WORRALL | T9: 1 | U9: Elena Dos Santos Gomez | X9: THomas Mouritzen | AA9: 1 | AB9: 1 | AC9: 1 | AD9: 1 | AE9: 1 | AF9: 1
A10: 8 | B10: Single | C10: Alexander Walcher | G10: 1 | I10: Han Michelle | L10: 1 | M10: Ratchabhorn Becker | P10: 1 | Q10: Fiona Harney | W10: 1 | AA10: MINGYUE MO (agoda) 1710588895 | AE10: 1 | AF10: 1
A11: 9 | B11: Single Queen | C11: Claudio Helmer | E11: extend 900 Paid by cash | I11: Jen Tong | P11: 1 | Q11: 1 | R11: Christopher Price | V11: 1 | W11: Naila MEFTAH | AB11: 1 | AC11: Jasmin Trocker
A12: 10 | B12: Twin Bed | C12: 1 | D12: 1 | I12: 1 | J12: Olivia Studsgaard 11:00 - 12:00 | N12: Pii Fang (Pii Dao' friend) Make King size bed | V12: TORRES HERMANSEN (988874866) | Z12: 1 | AA12: 1 | AB12: 1 | AC12: 1 | AD12: 1 | AE12: 1 | AF12: 1
A13: 11 | B13: Twin Bed | C13: Arthur Lyons | E13: Dominic Lowen make king size bed | H13: Marine Oussaiden / Change from Deluxe ->Twin bed | N13: David Bonicillo | R13: 1 | S13: Joano Freire | V13: 1 | W13: 1 | X13: 1 | Y13: 1 | Z13: 1 | AA13: 1 | AB13: 1 | AC13: 1 | AD13: 1 | AE13: 1 | AF13: 1
A14: 12 | B14: Single | C14: Tamera hutcherson | F14: Pii Dao 800 | G14: 1 | H14: eleonora lori | K14: 1 | L14: 1 | M14: Yasmin Gallagher(1:00-2:00)Pm | P14: Anke Pohlmann | S14: 1 | T14: 1 | U14: 1 | V14: 1 | W14: 1 | X14: 1 | Y14: 1 | Z14: 1 | AA14: 1 | AE14: Lilou THIVOLLE
A15: Suite | B15: Honeymoon | C15: 1 | D15: Flavia Culcasi | G15: 1 | H15: 1 | I15: 1 | J15: Craig Bessant 3:00 PM - 4:00 PM | O15: Boss - Pii Aoom | Q15: Alexa Diaz Quiroz | T15: 1 | U15: 1 | V15: 1 | W15: 1 | AF15: 1
C16: =(30*13-SUM(C17:AF20))/(30*13) -> 0.68461538
B17: Superiroe | C17: =C28+C34 -> 0 | D17: =D28+D34 -> 0 | E17: =E28+E34 -> 0 | F17: =F28+F34 -> 0 | G17: =G28+G34 -> 0 | H17: =H28+H34 -> 0 | I17: =I28+I34 -> 0 | J17: =J28+J34 -> 0 | ... AF17: =AF28+AF34 -> 0
B18: Deluxe Double | C18: =C26+C27+C31+C32+C33+C37 -> 3 | D18: =D26+D27+D31+D32+D33+D37 -> 1 | E18: =E26+E27+E31+E32+E33+E37 -> 1 | F18: =F26+F27+F31+F32+F33+F37 -> 0 | G18: =G26+G27+G31+G32+G33+G37 -> 2 | H18: =H26+H27+H31+H32+H33+H37 -> 0 | I18: =I26+I27+I31+I32+I33+I37 -> 1 | J18: =J26+J27+J31+J32+J33+J37 -> 0 | ... AF18: =AF26+AF27+AF31+AF32+AF33+AF37 -> 3
B19: DeluxeTwin | C19: =C29+C30+C35+C36 -> 3 | D19: =D29+D30+D35+D36 -> 3 | E19: =E29+E30+E35+E36 -> 2 | F19: =F29+F30+F35+F36 -> 2 | G19: =G29+G30+G35+G36 -> 1 | H19: =H29+H30+H35+H36 -> 1 | I19: =I29+I30+I35+I36 -> 1 | J19: =J29+J30+J35+J36 -> 1 | ... AF19: =AF29+AF30+AF35+AF36 -> 2
B20: Honeymoon Suite | C20: =C38 -> 1 | D20: =D38 -> 0 | E20: =E38 -> 0 | F20: =F38 -> 0 | G20: =G38 -> 1 | H20: =H38 -> 1 | I20: =I38 -> 1 | J20: =J38 -> 0 | ... AF20: =AF38 -> 1
C21: =SUM(C17:C20) -> 7 | D21: =SUM(D17:D20) -> 4 | E21: =SUM(E17:E20) -> 3 | F21: =SUM(F17:F20) -> 2 | G21: =SUM(G17:G20) -> 4 | H21: =SUM(H17:H20) -> 2 | I21: =SUM(I17:I20) -> 3 | J21: =SUM(J17:J20) -> 1 | ... AF21: =SUM(AF17:AF20) -> 6
B26: 1 | C26: =IF(C3=1,1,0) -> 1 | D26: =IF(D3=1,1,0) -> 0 | E26: =IF(E3=1,1,0) -> 0 | F26: =IF(F3=1,1,0) -> 0 | G26: =IF(G3=1,1,0) -> 0 | H26: =IF(H3=1,1,0) -> 0 | I26: =IF(I3=1,1,0) -> 0 | J26: =IF(J3=1,1,0) -> 0 | ... AF26: =IF(AF3=1,1,0) -> 1
B27: 2 | C27: =IF(C4=1,1,0) -> 1 | D27: =IF(D4=1,1,0) -> 0 | E27: =IF(E4=1,1,0) -> 0 | F27: =IF(F4=1,1,0) -> 0 | G27: =IF(G4=1,1,0) -> 0 | H27: =IF(H4=1,1,0) -> 0 | I27: =IF(I4=1,1,0) -> 1 | J27: =IF(J4=1,1,0) -> 0 | ... AF27: =IF(AF4=1,1,0) -> 0
B28: 3 | C28: =IF(C5=1,1,0) -> 0 | D28: =IF(D5=1,1,0) -> 0 | E28: =IF(E5=1,1,0) -> 0 | F28: =IF(F5=1,1,0) -> 0 | G28: =IF(G5=1,1,0) -> 0 | H28: =IF(H5=1,1,0) -> 0 | I28: =IF(I5=1,1,0) -> 0 | J28: =IF(J5=1,1,0) -> 0 | ... AF28: =IF(AF5=1,1,0) -> 0
B29: 4 | C29: =IF(C6=1,1,0) -> 1 | D29: =IF(D6=1,1,0) -> 1 | E29: =IF(E6=1,1,0) -> 1 | F29: =IF(F6=1,1,0) -> 1 | G29: =IF(G6=1,1,0) -> 1 | H29: =IF(H6=1,1,0) -> 1 | I29: =IF(I6=1,1,0) -> 0 | J29: =IF(J6=1,1,0) -> 0 | ... AF29: =IF(AF6=1,1,0) -> 0
B30: 5 | C30: =IF(C7=1,1,0) -> 1 | D30: =IF(D7=1,1,0) -> 1 | E30: =IF(E7=1,1,0) -> 1 | F30: =IF(F7=1,1,0) -> 1 | G30: =IF(G7=1,1,0) -> 0 | H30: =IF(H7=1,1,0) -> 0 | I30: =IF(I7=1,1,0) -> 0 | J30: =IF(J7=1,1,0) -> 1 | ... AF30: =IF(AF7=1,1,0) -> 0
B31: 6 | C31: =IF(C8=1,1,0) -> 1 | D31: =IF(D8=1,1,0) -> 1 | E31: =IF(E8=1,1,0) -> 1 | F31: =IF(F8=1,1,0) -> 0 | G31: =IF(G8=1,1,0) -> 0 | H31: =IF(H8=1,1,0) -> 0 | I31: =IF(I8=1,1,0) -> 0 | J31: =IF(J8=1,1,0) -> 0 | ... AF31: =IF(AF8=1,1,0) -> 0
B32: 7 | C32: =IF(C9=1,1,0) -> 0 | D32: =IF(D9=1,1,0) -> 0 | E32: =IF(E9=1,1,0) -> 0 | F32: =IF(F9=1,1,0) -> 0 | G32: =IF(G9=1,1,0) -> 0 | H32: =IF(H9=1,1,0) -> 0 | I32: =IF(I9=1,1,0) -> 0 | J32: =IF(J9=1,1,0) -> 0 | ... AF32: =IF(AF9=1,1,0) -> 1
B33: 8 | C33: =IF(C10=1,1,0) -> 0 | D33: =IF(D10=1,1,0) -> 0 | E33: =IF(E10=1,1,0) -> 0 | F33: =IF(F10=1,1,0) -> 0 | G33: =IF(G10=1,1,0) -> 1 | H33: =IF(H10=1,1,0) -> 0 | I33: =IF(I10=1,1,0) -> 0 | J33: =IF(J10=1,1,0) -> 0 | ... AF33: =IF(AF10=1,1,0) -> 1
B34: 9 | C34: =IF(C11=1,1,0) -> 0 | D34: =IF(D11=1,1,0) -> 0 | E34: =IF(E11=1,1,0) -> 0 | F34: =IF(F11=1,1,0) -> 0 | G34: =IF(G11=1,1,0) -> 0 | H34: =IF(H11=1,1,0) -> 0 | I34: =IF(I11=1,1,0) -> 0 | J34: =IF(J11=1,1,0) -> 0 | ... AF34: =IF(AF11=1,1,0) -> 0
B35: 10 | C35: =IF(C12=1,1,0) -> 1 | D35: =IF(D12=1,1,0) -> 1 | E35: =IF(E12=1,1,0) -> 0 | F35: =IF(F12=1,1,0) -> 0 | G35: =IF(G12=1,1,0) -> 0 | H35: =IF(H12=1,1,0) -> 0 | I35: =IF(I12=1,1,0) -> 1 | J35: =IF(J12=1,1,0) -> 0 | ... AF35: =IF(AF12=1,1,0) -> 1
B36: 11 | C36: =IF(C13=1,1,0) -> 0 | D36: =IF(D13=1,1,0) -> 0 | E36: =IF(E13=1,1,0) -> 0 | F36: =IF(F13=1,1,0) -> 0 | G36: =IF(G13=1,1,0) -> 0 | H36: =IF(H13=1,1,0) -> 0 | I36: =IF(I13=1,1,0) -> 0 | J36: =IF(J13=1,1,0) -> 0 | ... AF36: =IF(AF13=1,1,0) -> 1
B37: 12 | C37: =IF(C14=1,1,0) -> 0 | D37: =IF(D14=1,1,0) -> 0 | E37: =IF(E14=1,1,0) -> 0 | F37: =IF(F14=1,1,0) -> 0 | G37: =IF(G14=1,1,0) -> 1 | H37: =IF(H14=1,1,0) -> 0 | I37: =IF(I14=1,1,0) -> 0 | J37: =IF(J14=1,1,0) -> 0 | ... AF37: =IF(AF14=1,1,0) -> 0
B38: Suite | C38: =IF(C15=1,1,0) -> 1 | D38: =IF(D15=1,1,0) -> 0 | E38: =IF(E15=1,1,0) -> 0 | F38: =IF(F15=1,1,0) -> 0 | G38: =IF(G15=1,1,0) -> 1 | H38: =IF(H15=1,1,0) -> 1 | I38: =IF(I15=1,1,0) -> 1 | J38: =IF(J15=1,1,0) -> 0 | ... AF38: =IF(AF15=1,1,0) -> 1

Sheet May2026 
A1: Room | B1: Type | C1: 1 | D1: 2 | E1: 3 | F1: 4 | G1: 5 | H1: 6 | I1: 7 | J1: 8 | K1: 9 | L1: 10 | M1: 11 | N1: 12 | O1: 13 | P1: 14 | Q1: 15 | R1: 16 | S1: 17 | T1: 18 | U1: 19 | V1: 20 | W1: 21 | X1: 22 | Y1: 23 | Z1: 24 | AA1: 25 | AB1: 26 | AC1: 27 | AD1: 28 | AE1: 29 | AF1: 30 | AG1: 31
C2: Fri | D2: Sat | E2: Sun | F2: Mon | G2: Tue | H2: Wed | I2: Thu | J2: Fri | K2: Sat | L2: Sun | M2: Mon | N2: Tue | O2: Wed | P2: Thu | Q2: Fri | R2: Sat | S2: Sun | T2: Mon | U2: Tue | V2: Wed | W2: Thu | X2: Fri | Y2: Sat | Z2: Sun | AA2: Mon | AB2: Tue | AC2: Wed | AD2: Thu | AE2: Fri | AF2: Sat | AG2: Sun
A3: 1 | B3: Single | C3: 1 | D3: Marie Kruger | G3: Heather Zamenski | K3: 1 | L3: Ronja Schaub | Q3: 1 | R3: 1 | S3: 1 | T3: 1 | U3: 1 | V3: 1 | W3: Mathias Carrere | Z3: 1 | AA3: 1 | AB3: 1 | AC3: 1 | AD3: 1 | AE3: 1 | AF3: 1 | AG3: 1
A4: 2 | B4: Single | C4: Janto Groeneveld | D4: YUKA TOBISE | Q4: Roos Kerkhof | U4: 1 | V4: 1 | W4: 1 | X4: 1 | Y4: 1 | Z4: 1 | AA4: Corey Rudman | AD4: Hari Prasana/Dinesh Saravanan
A5: 3 | B5: Single Queen | C5: Bryan Paul Badong | F5: Karoline Foote | I5: 1 | J5: 1 | K5: 1 | L5: 1 | M5: 1 | N5: 1 | P5: WEN SHIHNI | AD5: Jessica Mc Donnell | AG5: 1
A6: 4 | B6: Twin Bed | C6: yiyian liang | G6: 1 | H6: 1 | I6: 1 | J6: Ruth Staunton | N6: 1 | O6: 1 | P6: 1 | Q6: 1 | R6: 1 | S6: 1 | T6: 1 | U6: 1 | V6: 1 | W6: Miguel Conde Luis Arturo | Z6: 1 | AA6: Aidan Nemiroff | AD6: Dinesh Saravanan Kumaraswamy | AG6: 1
A7: 5 | B7: Twin Bed | C7: Agnes Romagny | I7: 1 | J7: Fatimah Rahima Jingona 1675017172 / Reserve King Bad requested Twin Bed | P7: 1 | Q7: 1 | R7: 1 | S7: 1 | T7: 1 | U7: 1 | V7: 1 | W7: 1 | X7: Cassandra Tyros | AC7: 1 | AG7: 1
A8: 6 | B8: Single | C8: Warren Fouemena | H8: 1 | I8: 1 | J8: 1 | K8: 1 | L8: 1 | M8: 1 | N8: 1 | O8: Abigail Dixon | S8: 1 | T8: 1 | U8: 1 | V8: 1 | W8: 1 | X8: Claire Marques Pacheco 23:00 - 00:00 | AA8: Ryder Sitcawich | AG8: munirih mclaren
A9: 7 | B9: Single | C9: 1 | D9: 1 | E9: 1 | F9: Winson Lim | J9: Hury Alejandra Adams Garcia | M9: 1 | N9: 1 | O9: 1 | P9: 1 | Q9: 1 | R9: 1 | S9: Daisy Bradanini | V9: 1 | W9: 1 | X9: 1 | Y9: Ariana Teresa Viera Liceaga (2 Rooms) | AB9: 1 | AC9: 1 | AD9: 1 | AE9: Dinesh (Pay when Check in room 4 3,600) | AG9: 1
A10: 8 | B10: Single | C10: 1 | D10: 1 | E10: Claudia Nagel | I10: Klara Dowds | M10: 1 | N10: 1 | O10: 1 | P10: 1 | Q10: 1 | R10: 1 | S10: 1 | T10: 1 | U10: 1 | V10: 1 | W10: 1 | X10: 1 | AB10: 1 | AC10: 1 | AD10: 1 | AG10: 1
A11: 9 | B11: Single Queen | E11: Anna Georgiou | I11: 1 | J11: 1 | K11: 1 | L11: 1 | M11: Mujda Raufi | R11: Valentina Sarris | AF11: 1 | AG11: 1
A12: 10 | B12: Twin Bed | C12: b | D12: 1 | E12: 1 | F12: 1 | G12: 1 | H12: 1 | I12: 1 | J12: Samuel Delgado Muñoz | M12: 1 | N12: 1 | O12: 1 | P12: 1 | Q12: 1 | R12: 1 | S12: 1 | T12: 1 | U12: 1 | V12: 1 | W12: 1 | X12: 1 | Y12: 1 | Z12: 1 | AA12: 1 | AB12: 1 | AC12: 1 | AD12: 1 | AE12: 1 | AF12: 1 | AG12: 1
A13: 11 | B13: Twin Bed | C13: 1 | D13: 1 | E13: 1 | F13: 1 | G13: 1 | H13: 1 | I13: 1 | J13: 1 | K13: 1 | L13: 1 | M13: 1 | N13: 1 | O13: 1 | P13: 1 | Q13: 1 | R13: Tess Warren (18:00 - 19:00) | W13: 1 | X13: 1 | Y13: 1 | Z13: 1 | AA13: 1 | AB13: 1 | AC13: 1 | AD13: 1 | AE13: 1 | AF13: 1 | AG13: 1
A14: 12 | B14: Single | C14: Lilou THIVOLLE | V14: 1 | W14: 1 | X14: 1 | Y14: 1 | Z14: 1 | AA14: 1 | AB14: 1 | AC14: 1 | AD14: 1 | AE14: 1 | AF14: 1 | AG14: 1
A15: Suite | B15: Honeymoon | C15: 1 | D15: 1 | E15: 1 | F15: 1 | G15: 1 | H15: 1 | J15: Isabelle Hermes | Q15: 1 | R15: 1 | S15: 1 | T15: 1 | U15: 1 | V15: 1 | W15: Miguel Conde Arturo | Z15: Lin Amy | AE15: 1 | AF15: 1 | AG15: 1
C16: =(30*13-SUM(C17:AF20))/(30*13) -> #REF!
B17: Superiroe | C17: =C28+C34 -> 0 | D17: =D28+D34 -> 0 | E17: =E28+E34 -> 0 | F17: =F28+F34 -> 0 | G17: =G28+G34 -> 0 | H17: =H28+H34 -> 0 | I17: =I28+I34 -> 2 | J17: =J28+J34 -> 2 | ... AG17: =AG28+AG34 -> 2
B18: Deluxe Double | C18: =C26+C27+C31+C32+C33+C37 -> 3 | D18: =D26+D27+D31+D32+D33+D37 -> 2 | E18: =E26+E27+E31+E32+E33+E37 -> 1 | F18: =F26+F27+F31+F32+F33+F37 -> 0 | G18: =G26+G27+G31+G32+G33+G37 -> 0 | H18: =H26+H27+H31+H32+H33+H37 -> 1 | I18: =I26+I27+I31+I32+I33+I37 -> 1 | J18: =J26+J27+J31+J32+J33+J37 -> 1 | ... AG18: =AG26+AG27+AG31+AG32+AG33+AG37 -> 4
B19: DeluxeTwin | C19: =C29+C30+C35+C36 -> 1 | D19: =D29+D30+D35+D36 -> 2 | E19: =E29+E30+E35+E36 -> 2 | F19: =F29+F30+F35+F36 -> 2 | G19: =G29+G30+G35+G36 -> 3 | H19: =H29+H30+H35+H36 -> 3 | I19: =I29+I30+I35+I36 -> 4 | J19: =J29+J30+J35+J36 -> 1 | ... AG19: =AG29+AG30+AG35+AG36 -> 4
B20: Honeymoon Suite | C20: =C38 -> 1 | D20: =D38 -> 1 | E20: =E38 -> 1 | F20: =F38 -> 1 | G20: =G38 -> 1 | H20: =H38 -> 1 | I20: =I38 -> 0 | J20: =J38 -> #REF! | ... AG20: =AG38 -> 1
C21: =SUM(C17:C20) -> 5 | D21: =SUM(D17:D20) -> 5 | E21: =SUM(E17:E20) -> 4 | F21: =SUM(F17:F20) -> 3 | G21: =SUM(G17:G20) -> 4 | H21: =SUM(H17:H20) -> 5 | I21: =SUM(I17:I20) -> 7 | J21: =SUM(J17:J20) -> #REF! | ... AG21: =SUM(AG17:AG20) -> 11
B26: 1 | C26: =IF(C3=1,1,0) -> 1 | D26: =IF(D3=1,1,0) -> 0 | E26: =IF(E3=1,1,0) -> 0 | F26: =IF(F3=1,1,0) -> 0 | G26: =IF(G3=1,1,0) -> 0 | H26: =IF(H3=1,1,0) -> 0 | I26: =IF(I3=1,1,0) -> 0 | J26: =IF(J3=1,1,0) -> 0 | ... AG26: =IF(AG3=1,1,0) -> 1
B27: 2 | C27: =IF(C4=1,1,0) -> 0 | D27: =IF(D4=1,1,0) -> 0 | E27: =IF(E4=1,1,0) -> 0 | F27: =IF(F4=1,1,0) -> 0 | G27: =IF(G4=1,1,0) -> 0 | H27: =IF(H4=1,1,0) -> 0 | I27: =IF(I4=1,1,0) -> 0 | J27: =IF(J4=1,1,0) -> 0 | ... AG27: =IF(AG4=1,1,0) -> 0
B28: 3 | C28: =IF(C5=1,1,0) -> 0 | D28: =IF(D5=1,1,0) -> 0 | E28: =IF(E5=1,1,0) -> 0 | F28: =IF(F5=1,1,0) -> 0 | G28: =IF(G5=1,1,0) -> 0 | H28: =IF(H5=1,1,0) -> 0 | I28: =IF(I5=1,1,0) -> 1 | J28: =IF(J5=1,1,0) -> 1 | ... AE28: =IF(AE5=1,1,0) -> 0 | AF28: =IF(AD5=1,1,0) -> 0 | AG28: =IF(AG5=1,1,0) -> 1
B29: 4 | C29: =IF(C6=1,1,0) -> 0 | D29: =IF(D6=1,1,0) -> 0 | E29: =IF(E6=1,1,0) -> 0 | F29: =IF(F6=1,1,0) -> 0 | G29: =IF(G6=1,1,0) -> 1 | H29: =IF(H6=1,1,0) -> 1 | I29: =IF(I6=1,1,0) -> 1 | J29: =IF(J6=1,1,0) -> 0 | ... AG29: =IF(AG6=1,1,0) -> 1
B30: 5 | C30: =IF(C7=1,1,0) -> 0 | D30: =IF(D7=1,1,0) -> 0 | E30: =IF(E7=1,1,0) -> 0 | F30: =IF(F7=1,1,0) -> 0 | G30: =IF(G7=1,1,0) -> 0 | H30: =IF(H7=1,1,0) -> 0 | I30: =IF(I7=1,1,0) -> 1 | J30: =IF(J7=1,1,0) -> 0 | ... AG30: =IF(AG7=1,1,0) -> 1
B31: 6 | C31: =IF(C8=1,1,0) -> 0 | D31: =IF(D8=1,1,0) -> 0 | E31: =IF(E8=1,1,0) -> 0 | F31: =IF(F8=1,1,0) -> 0 | G31: =IF(G8=1,1,0) -> 0 | H31: =IF(H8=1,1,0) -> 1 | I31: =IF(I8=1,1,0) -> 1 | J31: =IF(J8=1,1,0) -> 1 | ... AG31: =IF(AG8=1,1,0) -> 0
B32: 7 | C32: =IF(C9=1,1,0) -> 1 | D32: =IF(D9=1,1,0) -> 1 | E32: =IF(E9=1,1,0) -> 1 | F32: =IF(F9=1,1,0) -> 0 | G32: =IF(G9=1,1,0) -> 0 | H32: =IF(H9=1,1,0) -> 0 | I32: =IF(I9=1,1,0) -> 0 | J32: =IF(J9=1,1,0) -> 0 | ... AG32: =IF(AG9=1,1,0) -> 1
B33: 8 | C33: =IF(C10=1,1,0) -> 1 | D33: =IF(D10=1,1,0) -> 1 | E33: =IF(E10=1,1,0) -> 0 | F33: =IF(F10=1,1,0) -> 0 | G33: =IF(G10=1,1,0) -> 0 | H33: =IF(H10=1,1,0) -> 0 | I33: =IF(I10=1,1,0) -> 0 | J33: =IF(J10=1,1,0) -> 0 | ... AG33: =IF(AG10=1,1,0) -> 1
B34: 9 | C34: =IF(C11=1,1,0) -> 0 | D34: =IF(D11=1,1,0) -> 0 | E34: =IF(E11=1,1,0) -> 0 | F34: =IF(F11=1,1,0) -> 0 | G34: =IF(G11=1,1,0) -> 0 | H34: =IF(H11=1,1,0) -> 0 | I34: =IF(I11=1,1,0) -> 1 | J34: =IF(J11=1,1,0) -> 1 | ... AG34: =IF(AG11=1,1,0) -> 1
B35: 10 | C35: =IF(C12=1,1,0) -> 0 | D35: =IF(D12=1,1,0) -> 1 | E35: =IF(E12=1,1,0) -> 1 | F35: =IF(F12=1,1,0) -> 1 | G35: =IF(G12=1,1,0) -> 1 | H35: =IF(H12=1,1,0) -> 1 | I35: =IF(I12=1,1,0) -> 1 | J35: =IF(J12=1,1,0) -> 0 | ... AG35: =IF(AG12=1,1,0) -> 1
B36: 11 | C36: =IF(C13=1,1,0) -> 1 | D36: =IF(D13=1,1,0) -> 1 | E36: =IF(E13=1,1,0) -> 1 | F36: =IF(F13=1,1,0) -> 1 | G36: =IF(G13=1,1,0) -> 1 | H36: =IF(H13=1,1,0) -> 1 | I36: =IF(I13=1,1,0) -> 1 | J36: =IF(J13=1,1,0) -> 1 | ... AG36: =IF(AG13=1,1,0) -> 1
